2018-09-20 18:57:59,549 - tester - ERROR - 测试器发生错误Set of coroutines/Futures is empty.
Traceback (most recent call last):
  File "/home/python/Desktop/spider3/ProxyPool/proxypool/tester.py", line 66, in run
    loop.run_until_complete(asyncio.wait(tasks))
  File "/usr/lib/python3.5/asyncio/base_events.py", line 387, in run_until_complete
    return future.result()
  File "/usr/lib/python3.5/asyncio/futures.py", line 274, in result
    raise self._exception
  File "/usr/lib/python3.5/asyncio/tasks.py", line 239, in _step
    result = coro.send(None)
  File "/usr/lib/python3.5/asyncio/tasks.py", line 338, in wait
    raise ValueError('Set of coroutines/Futures is empty.')
ValueError: Set of coroutines/Futures is empty.
2018-09-20 19:17:06,031 - tester - ERROR - 测试器发生错误Set of coroutines/Futures is empty.
Traceback (most recent call last):
  File "/home/python/Desktop/spider3/ProxyPool/proxypool/tester.py", line 66, in run
    loop.run_until_complete(asyncio.wait(tasks))
  File "/usr/lib/python3.5/asyncio/base_events.py", line 387, in run_until_complete
    return future.result()
  File "/usr/lib/python3.5/asyncio/futures.py", line 274, in result
    raise self._exception
  File "/usr/lib/python3.5/asyncio/tasks.py", line 239, in _step
    result = coro.send(None)
  File "/usr/lib/python3.5/asyncio/tasks.py", line 338, in wait
    raise ValueError('Set of coroutines/Futures is empty.')
ValueError: Set of coroutines/Futures is empty.
2018-09-20 19:35:17,383 - tester - ERROR - 测试器发生错误Set of coroutines/Futures is empty.
Traceback (most recent call last):
  File "/home/python/Desktop/spider3/ProxyPool/proxypool/tester.py", line 66, in run
    loop.run_until_complete(asyncio.wait(tasks))
  File "/usr/lib/python3.5/asyncio/base_events.py", line 387, in run_until_complete
    return future.result()
  File "/usr/lib/python3.5/asyncio/futures.py", line 274, in result
    raise self._exception
  File "/usr/lib/python3.5/asyncio/tasks.py", line 239, in _step
    result = coro.send(None)
  File "/usr/lib/python3.5/asyncio/tasks.py", line 338, in wait
    raise ValueError('Set of coroutines/Futures is empty.')
ValueError: Set of coroutines/Futures is empty.
2018-09-20 20:02:12,548 - tester - ERROR - 测试器发生错误Set of coroutines/Futures is empty.
Traceback (most recent call last):
  File "/home/python/Desktop/spider3/ProxyPool/proxypool/tester.py", line 66, in run
    loop.run_until_complete(asyncio.wait(tasks))
  File "/usr/lib/python3.5/asyncio/base_events.py", line 387, in run_until_complete
    return future.result()
  File "/usr/lib/python3.5/asyncio/futures.py", line 274, in result
    raise self._exception
  File "/usr/lib/python3.5/asyncio/tasks.py", line 239, in _step
    result = coro.send(None)
  File "/usr/lib/python3.5/asyncio/tasks.py", line 338, in wait
    raise ValueError('Set of coroutines/Futures is empty.')
ValueError: Set of coroutines/Futures is empty.
2018-09-21 15:56:37,713 - tester - ERROR - 测试器发生错误Set of coroutines/Futures is empty.
Traceback (most recent call last):
  File "/home/python/Desktop/spider3/ProxyPool/proxypool/tester.py", line 66, in run
    loop.run_until_complete(asyncio.wait(tasks))
  File "/usr/lib/python3.5/asyncio/base_events.py", line 387, in run_until_complete
    return future.result()
  File "/usr/lib/python3.5/asyncio/futures.py", line 274, in result
    raise self._exception
  File "/usr/lib/python3.5/asyncio/tasks.py", line 239, in _step
    result = coro.send(None)
  File "/usr/lib/python3.5/asyncio/tasks.py", line 338, in wait
    raise ValueError('Set of coroutines/Futures is empty.')
ValueError: Set of coroutines/Futures is empty.
2018-09-21 16:02:35,711 - tester - ERROR - 测试器发生错误Set of coroutines/Futures is empty.
Traceback (most recent call last):
  File "/home/python/Desktop/spider3/ProxyPool/proxypool/tester.py", line 66, in run
    loop.run_until_complete(asyncio.wait(tasks))
  File "/usr/lib/python3.5/asyncio/base_events.py", line 387, in run_until_complete
    return future.result()
  File "/usr/lib/python3.5/asyncio/futures.py", line 274, in result
    raise self._exception
  File "/usr/lib/python3.5/asyncio/tasks.py", line 239, in _step
    result = coro.send(None)
  File "/usr/lib/python3.5/asyncio/tasks.py", line 338, in wait
    raise ValueError('Set of coroutines/Futures is empty.')
ValueError: Set of coroutines/Futures is empty.
2018-09-21 16:14:13,709 - tester - ERROR - 测试器发生错误Set of coroutines/Futures is empty.
Traceback (most recent call last):
  File "/home/python/Desktop/spider3/ProxyPool/proxypool/tester.py", line 66, in run
    loop.run_until_complete(asyncio.wait(tasks))
  File "/usr/lib/python3.5/asyncio/base_events.py", line 387, in run_until_complete
    return future.result()
  File "/usr/lib/python3.5/asyncio/futures.py", line 274, in result
    raise self._exception
  File "/usr/lib/python3.5/asyncio/tasks.py", line 239, in _step
    result = coro.send(None)
  File "/usr/lib/python3.5/asyncio/tasks.py", line 338, in wait
    raise ValueError('Set of coroutines/Futures is empty.')
ValueError: Set of coroutines/Futures is empty.
2018-09-21 16:44:51,722 - tester - ERROR - 测试器发生错误Set of coroutines/Futures is empty.
Traceback (most recent call last):
  File "/home/python/Desktop/spider3/ProxyPool/proxypool/tester.py", line 66, in run
    loop.run_until_complete(asyncio.wait(tasks))
  File "/usr/lib/python3.5/asyncio/base_events.py", line 387, in run_until_complete
    return future.result()
  File "/usr/lib/python3.5/asyncio/futures.py", line 274, in result
    raise self._exception
  File "/usr/lib/python3.5/asyncio/tasks.py", line 239, in _step
    result = coro.send(None)
  File "/usr/lib/python3.5/asyncio/tasks.py", line 338, in wait
    raise ValueError('Set of coroutines/Futures is empty.')
ValueError: Set of coroutines/Futures is empty.
2018-09-21 16:54:13,729 - tester - ERROR - 测试器发生错误Set of coroutines/Futures is empty.
Traceback (most recent call last):
  File "/home/python/Desktop/spider3/ProxyPool/proxypool/tester.py", line 66, in run
    loop.run_until_complete(asyncio.wait(tasks))
  File "/usr/lib/python3.5/asyncio/base_events.py", line 387, in run_until_complete
    return future.result()
  File "/usr/lib/python3.5/asyncio/futures.py", line 274, in result
    raise self._exception
  File "/usr/lib/python3.5/asyncio/tasks.py", line 239, in _step
    result = coro.send(None)
  File "/usr/lib/python3.5/asyncio/tasks.py", line 338, in wait
    raise ValueError('Set of coroutines/Futures is empty.')
ValueError: Set of coroutines/Futures is empty.
2018-09-21 17:03:46,710 - tester - ERROR - 测试器发生错误Set of coroutines/Futures is empty.
Traceback (most recent call last):
  File "/home/python/Desktop/spider3/ProxyPool/proxypool/tester.py", line 66, in run
    loop.run_until_complete(asyncio.wait(tasks))
  File "/usr/lib/python3.5/asyncio/base_events.py", line 387, in run_until_complete
    return future.result()
  File "/usr/lib/python3.5/asyncio/futures.py", line 274, in result
    raise self._exception
  File "/usr/lib/python3.5/asyncio/tasks.py", line 239, in _step
    result = coro.send(None)
  File "/usr/lib/python3.5/asyncio/tasks.py", line 338, in wait
    raise ValueError('Set of coroutines/Futures is empty.')
ValueError: Set of coroutines/Futures is empty.
2018-09-21 17:11:52,718 - tester - ERROR - 测试器发生错误Set of coroutines/Futures is empty.
Traceback (most recent call last):
  File "/home/python/Desktop/spider3/ProxyPool/proxypool/tester.py", line 66, in run
    loop.run_until_complete(asyncio.wait(tasks))
  File "/usr/lib/python3.5/asyncio/base_events.py", line 387, in run_until_complete
    return future.result()
  File "/usr/lib/python3.5/asyncio/futures.py", line 274, in result
    raise self._exception
  File "/usr/lib/python3.5/asyncio/tasks.py", line 239, in _step
    result = coro.send(None)
  File "/usr/lib/python3.5/asyncio/tasks.py", line 338, in wait
    raise ValueError('Set of coroutines/Futures is empty.')
ValueError: Set of coroutines/Futures is empty.
2018-09-21 17:22:06,731 - tester - ERROR - 测试器发生错误Set of coroutines/Futures is empty.
Traceback (most recent call last):
  File "/home/python/Desktop/spider3/ProxyPool/proxypool/tester.py", line 66, in run
    loop.run_until_complete(asyncio.wait(tasks))
  File "/usr/lib/python3.5/asyncio/base_events.py", line 387, in run_until_complete
    return future.result()
  File "/usr/lib/python3.5/asyncio/futures.py", line 274, in result
    raise self._exception
  File "/usr/lib/python3.5/asyncio/tasks.py", line 239, in _step
    result = coro.send(None)
  File "/usr/lib/python3.5/asyncio/tasks.py", line 338, in wait
    raise ValueError('Set of coroutines/Futures is empty.')
ValueError: Set of coroutines/Futures is empty.
2018-09-21 17:31:34,734 - tester - ERROR - 测试器发生错误Set of coroutines/Futures is empty.
Traceback (most recent call last):
  File "/home/python/Desktop/spider3/ProxyPool/proxypool/tester.py", line 66, in run
    loop.run_until_complete(asyncio.wait(tasks))
  File "/usr/lib/python3.5/asyncio/base_events.py", line 387, in run_until_complete
    return future.result()
  File "/usr/lib/python3.5/asyncio/futures.py", line 274, in result
    raise self._exception
  File "/usr/lib/python3.5/asyncio/tasks.py", line 239, in _step
    result = coro.send(None)
  File "/usr/lib/python3.5/asyncio/tasks.py", line 338, in wait
    raise ValueError('Set of coroutines/Futures is empty.')
ValueError: Set of coroutines/Futures is empty.
2018-09-21 17:59:03,710 - tester - ERROR - 测试器发生错误Set of coroutines/Futures is empty.
Traceback (most recent call last):
  File "/home/python/Desktop/spider3/ProxyPool/proxypool/tester.py", line 66, in run
    loop.run_until_complete(asyncio.wait(tasks))
  File "/usr/lib/python3.5/asyncio/base_events.py", line 387, in run_until_complete
    return future.result()
  File "/usr/lib/python3.5/asyncio/futures.py", line 274, in result
    raise self._exception
  File "/usr/lib/python3.5/asyncio/tasks.py", line 239, in _step
    result = coro.send(None)
  File "/usr/lib/python3.5/asyncio/tasks.py", line 338, in wait
    raise ValueError('Set of coroutines/Futures is empty.')
ValueError: Set of coroutines/Futures is empty.
2018-09-21 18:07:49,707 - tester - ERROR - 测试器发生错误Set of coroutines/Futures is empty.
Traceback (most recent call last):
  File "/home/python/Desktop/spider3/ProxyPool/proxypool/tester.py", line 66, in run
    loop.run_until_complete(asyncio.wait(tasks))
  File "/usr/lib/python3.5/asyncio/base_events.py", line 387, in run_until_complete
    return future.result()
  File "/usr/lib/python3.5/asyncio/futures.py", line 274, in result
    raise self._exception
  File "/usr/lib/python3.5/asyncio/tasks.py", line 239, in _step
    result = coro.send(None)
  File "/usr/lib/python3.5/asyncio/tasks.py", line 338, in wait
    raise ValueError('Set of coroutines/Futures is empty.')
ValueError: Set of coroutines/Futures is empty.
2018-09-21 18:18:36,722 - tester - ERROR - 测试器发生错误Set of coroutines/Futures is empty.
Traceback (most recent call last):
  File "/home/python/Desktop/spider3/ProxyPool/proxypool/tester.py", line 66, in run
    loop.run_until_complete(asyncio.wait(tasks))
  File "/usr/lib/python3.5/asyncio/base_events.py", line 387, in run_until_complete
    return future.result()
  File "/usr/lib/python3.5/asyncio/futures.py", line 274, in result
    raise self._exception
  File "/usr/lib/python3.5/asyncio/tasks.py", line 239, in _step
    result = coro.send(None)
  File "/usr/lib/python3.5/asyncio/tasks.py", line 338, in wait
    raise ValueError('Set of coroutines/Futures is empty.')
ValueError: Set of coroutines/Futures is empty.
2018-09-21 18:27:03,719 - tester - ERROR - 测试器发生错误Set of coroutines/Futures is empty.
Traceback (most recent call last):
  File "/home/python/Desktop/spider3/ProxyPool/proxypool/tester.py", line 66, in run
    loop.run_until_complete(asyncio.wait(tasks))
  File "/usr/lib/python3.5/asyncio/base_events.py", line 387, in run_until_complete
    return future.result()
  File "/usr/lib/python3.5/asyncio/futures.py", line 274, in result
    raise self._exception
  File "/usr/lib/python3.5/asyncio/tasks.py", line 239, in _step
    result = coro.send(None)
  File "/usr/lib/python3.5/asyncio/tasks.py", line 338, in wait
    raise ValueError('Set of coroutines/Futures is empty.')
ValueError: Set of coroutines/Futures is empty.
2018-09-21 18:28:49,694 - asyncio - ERROR - Fatal error on SSL transport
protocol: <asyncio.sslproto.SSLProtocol object at 0x7f98589b77b8>
transport: <_SelectorSocketTransport closing fd=20 read=idle write=<idle, bufsize=0>>
Traceback (most recent call last):
  File "/usr/lib/python3.5/asyncio/sslproto.py", line 628, in _process_write_backlog
    ssldata = self._sslpipe.shutdown(self._finalize)
  File "/usr/lib/python3.5/asyncio/sslproto.py", line 151, in shutdown
    raise RuntimeError('shutdown in progress')
RuntimeError: shutdown in progress
2018-09-21 18:29:30,719 - tester - ERROR - 测试器发生错误Set of coroutines/Futures is empty.
Traceback (most recent call last):
  File "/home/python/Desktop/spider3/ProxyPool/proxypool/tester.py", line 66, in run
    loop.run_until_complete(asyncio.wait(tasks))
  File "/usr/lib/python3.5/asyncio/base_events.py", line 387, in run_until_complete
    return future.result()
  File "/usr/lib/python3.5/asyncio/futures.py", line 274, in result
    raise self._exception
  File "/usr/lib/python3.5/asyncio/tasks.py", line 239, in _step
    result = coro.send(None)
  File "/usr/lib/python3.5/asyncio/tasks.py", line 338, in wait
    raise ValueError('Set of coroutines/Futures is empty.')
ValueError: Set of coroutines/Futures is empty.
2018-09-21 18:33:29,716 - tester - ERROR - 测试器发生错误Set of coroutines/Futures is empty.
Traceback (most recent call last):
  File "/home/python/Desktop/spider3/ProxyPool/proxypool/tester.py", line 66, in run
    loop.run_until_complete(asyncio.wait(tasks))
  File "/usr/lib/python3.5/asyncio/base_events.py", line 387, in run_until_complete
    return future.result()
  File "/usr/lib/python3.5/asyncio/futures.py", line 274, in result
    raise self._exception
  File "/usr/lib/python3.5/asyncio/tasks.py", line 239, in _step
    result = coro.send(None)
  File "/usr/lib/python3.5/asyncio/tasks.py", line 338, in wait
    raise ValueError('Set of coroutines/Futures is empty.')
ValueError: Set of coroutines/Futures is empty.
2018-09-21 18:33:49,702 - tester - ERROR - 测试器发生错误Set of coroutines/Futures is empty.
Traceback (most recent call last):
  File "/home/python/Desktop/spider3/ProxyPool/proxypool/tester.py", line 66, in run
    loop.run_until_complete(asyncio.wait(tasks))
  File "/usr/lib/python3.5/asyncio/base_events.py", line 387, in run_until_complete
    return future.result()
  File "/usr/lib/python3.5/asyncio/futures.py", line 274, in result
    raise self._exception
  File "/usr/lib/python3.5/asyncio/tasks.py", line 239, in _step
    result = coro.send(None)
  File "/usr/lib/python3.5/asyncio/tasks.py", line 338, in wait
    raise ValueError('Set of coroutines/Futures is empty.')
ValueError: Set of coroutines/Futures is empty.
2018-09-21 18:39:33,710 - tester - ERROR - 测试器发生错误Set of coroutines/Futures is empty.
Traceback (most recent call last):
  File "/home/python/Desktop/spider3/ProxyPool/proxypool/tester.py", line 66, in run
    loop.run_until_complete(asyncio.wait(tasks))
  File "/usr/lib/python3.5/asyncio/base_events.py", line 387, in run_until_complete
    return future.result()
  File "/usr/lib/python3.5/asyncio/futures.py", line 274, in result
    raise self._exception
  File "/usr/lib/python3.5/asyncio/tasks.py", line 239, in _step
    result = coro.send(None)
  File "/usr/lib/python3.5/asyncio/tasks.py", line 338, in wait
    raise ValueError('Set of coroutines/Futures is empty.')
ValueError: Set of coroutines/Futures is empty.
2018-09-21 18:39:42,709 - tester - ERROR - 测试器发生错误Set of coroutines/Futures is empty.
Traceback (most recent call last):
  File "/home/python/Desktop/spider3/ProxyPool/proxypool/tester.py", line 66, in run
    loop.run_until_complete(asyncio.wait(tasks))
  File "/usr/lib/python3.5/asyncio/base_events.py", line 387, in run_until_complete
    return future.result()
  File "/usr/lib/python3.5/asyncio/futures.py", line 274, in result
    raise self._exception
  File "/usr/lib/python3.5/asyncio/tasks.py", line 239, in _step
    result = coro.send(None)
  File "/usr/lib/python3.5/asyncio/tasks.py", line 338, in wait
    raise ValueError('Set of coroutines/Futures is empty.')
ValueError: Set of coroutines/Futures is empty.
2018-09-21 18:46:52,729 - tester - ERROR - 测试器发生错误Set of coroutines/Futures is empty.
Traceback (most recent call last):
  File "/home/python/Desktop/spider3/ProxyPool/proxypool/tester.py", line 66, in run
    loop.run_until_complete(asyncio.wait(tasks))
  File "/usr/lib/python3.5/asyncio/base_events.py", line 387, in run_until_complete
    return future.result()
  File "/usr/lib/python3.5/asyncio/futures.py", line 274, in result
    raise self._exception
  File "/usr/lib/python3.5/asyncio/tasks.py", line 239, in _step
    result = coro.send(None)
  File "/usr/lib/python3.5/asyncio/tasks.py", line 338, in wait
    raise ValueError('Set of coroutines/Futures is empty.')
ValueError: Set of coroutines/Futures is empty.
2018-09-21 18:46:54,729 - tester - ERROR - 测试器发生错误Set of coroutines/Futures is empty.
Traceback (most recent call last):
  File "/home/python/Desktop/spider3/ProxyPool/proxypool/tester.py", line 66, in run
    loop.run_until_complete(asyncio.wait(tasks))
  File "/usr/lib/python3.5/asyncio/base_events.py", line 387, in run_until_complete
    return future.result()
  File "/usr/lib/python3.5/asyncio/futures.py", line 274, in result
    raise self._exception
  File "/usr/lib/python3.5/asyncio/tasks.py", line 239, in _step
    result = coro.send(None)
  File "/usr/lib/python3.5/asyncio/tasks.py", line 338, in wait
    raise ValueError('Set of coroutines/Futures is empty.')
ValueError: Set of coroutines/Futures is empty.
2018-09-21 18:52:14,737 - asyncio - ERROR - Task exception was never retrieved
future: <Task finished coro=<Tester.test_single_proxy() done, defined at /home/python/Desktop/spider3/ProxyPool/proxypool/tester.py:20> exception=TypeError('%d format: a number is required, not NoneType',)>
Traceback (most recent call last):
  File "/home/python/Desktop/spider3/ProxyPool/proxypool/tester.py", line 35, in test_single_proxy
    async with session.get(TEST_URL, proxy=real_proxy, timeout=5, allow_redirects=False) as response:
  File "/home/python/.virtualenvs/Env1/lib/python3.5/site-packages/aiohttp/client.py", line 690, in __aenter__
    self._resp = yield from self._coro
  File "/home/python/.virtualenvs/Env1/lib/python3.5/site-packages/aiohttp/client.py", line 341, in _request
    break
  File "/home/python/.virtualenvs/Env1/lib/python3.5/site-packages/aiohttp/helpers.py", line 732, in __exit__
    raise asyncio.TimeoutError from None
concurrent.futures._base.TimeoutError

During handling of the above exception, another exception occurred:

Traceback (most recent call last):
  File "/usr/lib/python3.5/asyncio/tasks.py", line 241, in _step
    result = coro.throw(exc)
  File "/home/python/Desktop/spider3/ProxyPool/proxypool/tester.py", line 44, in test_single_proxy
    self.redis.decrease(proxy)
  File "/home/python/Desktop/spider3/ProxyPool/proxypool/db.py", line 77, in decrease
    logger.info('代理%s, 当前分数%d移除' % (proxy, score))
TypeError: %d format: a number is required, not NoneType
2018-09-21 18:52:14,748 - asyncio - ERROR - Task exception was never retrieved
future: <Task finished coro=<Tester.test_single_proxy() done, defined at /home/python/Desktop/spider3/ProxyPool/proxypool/tester.py:20> exception=TypeError('%d format: a number is required, not NoneType',)>
Traceback (most recent call last):
  File "/home/python/Desktop/spider3/ProxyPool/proxypool/tester.py", line 35, in test_single_proxy
    async with session.get(TEST_URL, proxy=real_proxy, timeout=5, allow_redirects=False) as response:
  File "/home/python/.virtualenvs/Env1/lib/python3.5/site-packages/aiohttp/client.py", line 690, in __aenter__
    self._resp = yield from self._coro
  File "/home/python/.virtualenvs/Env1/lib/python3.5/site-packages/aiohttp/client.py", line 341, in _request
    break
  File "/home/python/.virtualenvs/Env1/lib/python3.5/site-packages/aiohttp/helpers.py", line 732, in __exit__
    raise asyncio.TimeoutError from None
concurrent.futures._base.TimeoutError

During handling of the above exception, another exception occurred:

Traceback (most recent call last):
  File "/usr/lib/python3.5/asyncio/tasks.py", line 241, in _step
    result = coro.throw(exc)
  File "/home/python/Desktop/spider3/ProxyPool/proxypool/tester.py", line 44, in test_single_proxy
    self.redis.decrease(proxy)
  File "/home/python/Desktop/spider3/ProxyPool/proxypool/db.py", line 77, in decrease
    logger.info('代理%s, 当前分数%d移除' % (proxy, score))
TypeError: %d format: a number is required, not NoneType
2018-09-21 18:52:14,748 - asyncio - ERROR - Task exception was never retrieved
future: <Task finished coro=<Tester.test_single_proxy() done, defined at /home/python/Desktop/spider3/ProxyPool/proxypool/tester.py:20> exception=TypeError('%d format: a number is required, not NoneType',)>
Traceback (most recent call last):
  File "/home/python/Desktop/spider3/ProxyPool/proxypool/tester.py", line 35, in test_single_proxy
    async with session.get(TEST_URL, proxy=real_proxy, timeout=5, allow_redirects=False) as response:
  File "/home/python/.virtualenvs/Env1/lib/python3.5/site-packages/aiohttp/client.py", line 690, in __aenter__
    self._resp = yield from self._coro
  File "/home/python/.virtualenvs/Env1/lib/python3.5/site-packages/aiohttp/client.py", line 341, in _request
    break
  File "/home/python/.virtualenvs/Env1/lib/python3.5/site-packages/aiohttp/helpers.py", line 732, in __exit__
    raise asyncio.TimeoutError from None
concurrent.futures._base.TimeoutError

During handling of the above exception, another exception occurred:

Traceback (most recent call last):
  File "/usr/lib/python3.5/asyncio/tasks.py", line 241, in _step
    result = coro.throw(exc)
  File "/home/python/Desktop/spider3/ProxyPool/proxypool/tester.py", line 44, in test_single_proxy
    self.redis.decrease(proxy)
  File "/home/python/Desktop/spider3/ProxyPool/proxypool/db.py", line 77, in decrease
    logger.info('代理%s, 当前分数%d移除' % (proxy, score))
TypeError: %d format: a number is required, not NoneType
2018-09-21 18:52:14,751 - asyncio - ERROR - Task exception was never retrieved
future: <Task finished coro=<Tester.test_single_proxy() done, defined at /home/python/Desktop/spider3/ProxyPool/proxypool/tester.py:20> exception=TypeError('%d format: a number is required, not NoneType',)>
Traceback (most recent call last):
  File "/home/python/Desktop/spider3/ProxyPool/proxypool/tester.py", line 35, in test_single_proxy
    async with session.get(TEST_URL, proxy=real_proxy, timeout=5, allow_redirects=False) as response:
  File "/home/python/.virtualenvs/Env1/lib/python3.5/site-packages/aiohttp/client.py", line 690, in __aenter__
    self._resp = yield from self._coro
  File "/home/python/.virtualenvs/Env1/lib/python3.5/site-packages/aiohttp/client.py", line 341, in _request
    break
  File "/home/python/.virtualenvs/Env1/lib/python3.5/site-packages/aiohttp/helpers.py", line 732, in __exit__
    raise asyncio.TimeoutError from None
concurrent.futures._base.TimeoutError

During handling of the above exception, another exception occurred:

Traceback (most recent call last):
  File "/usr/lib/python3.5/asyncio/tasks.py", line 241, in _step
    result = coro.throw(exc)
  File "/home/python/Desktop/spider3/ProxyPool/proxypool/tester.py", line 44, in test_single_proxy
    self.redis.decrease(proxy)
  File "/home/python/Desktop/spider3/ProxyPool/proxypool/db.py", line 77, in decrease
    logger.info('代理%s, 当前分数%d移除' % (proxy, score))
TypeError: %d format: a number is required, not NoneType
2018-09-21 18:53:09,714 - asyncio - ERROR - Task exception was never retrieved
future: <Task finished coro=<Tester.test_single_proxy() done, defined at /home/python/Desktop/spider3/ProxyPool/proxypool/tester.py:20> exception=TypeError('%d format: a number is required, not NoneType',)>
Traceback (most recent call last):
  File "/home/python/Desktop/spider3/ProxyPool/proxypool/tester.py", line 35, in test_single_proxy
    async with session.get(TEST_URL, proxy=real_proxy, timeout=5, allow_redirects=False) as response:
  File "/home/python/.virtualenvs/Env1/lib/python3.5/site-packages/aiohttp/client.py", line 690, in __aenter__
    self._resp = yield from self._coro
  File "/home/python/.virtualenvs/Env1/lib/python3.5/site-packages/aiohttp/client.py", line 341, in _request
    break
  File "/home/python/.virtualenvs/Env1/lib/python3.5/site-packages/aiohttp/helpers.py", line 732, in __exit__
    raise asyncio.TimeoutError from None
concurrent.futures._base.TimeoutError

During handling of the above exception, another exception occurred:

Traceback (most recent call last):
  File "/usr/lib/python3.5/asyncio/tasks.py", line 241, in _step
    result = coro.throw(exc)
  File "/home/python/Desktop/spider3/ProxyPool/proxypool/tester.py", line 44, in test_single_proxy
    self.redis.decrease(proxy)
  File "/home/python/Desktop/spider3/ProxyPool/proxypool/db.py", line 77, in decrease
    logger.info('代理%s, 当前分数%d移除' % (proxy, score))
TypeError: %d format: a number is required, not NoneType
2018-09-21 18:53:09,715 - asyncio - ERROR - Task exception was never retrieved
future: <Task finished coro=<Tester.test_single_proxy() done, defined at /home/python/Desktop/spider3/ProxyPool/proxypool/tester.py:20> exception=TypeError('%d format: a number is required, not NoneType',)>
Traceback (most recent call last):
  File "/home/python/Desktop/spider3/ProxyPool/proxypool/tester.py", line 35, in test_single_proxy
    async with session.get(TEST_URL, proxy=real_proxy, timeout=5, allow_redirects=False) as response:
  File "/home/python/.virtualenvs/Env1/lib/python3.5/site-packages/aiohttp/client.py", line 690, in __aenter__
    self._resp = yield from self._coro
  File "/home/python/.virtualenvs/Env1/lib/python3.5/site-packages/aiohttp/client.py", line 341, in _request
    break
  File "/home/python/.virtualenvs/Env1/lib/python3.5/site-packages/aiohttp/helpers.py", line 732, in __exit__
    raise asyncio.TimeoutError from None
concurrent.futures._base.TimeoutError

During handling of the above exception, another exception occurred:

Traceback (most recent call last):
  File "/usr/lib/python3.5/asyncio/tasks.py", line 241, in _step
    result = coro.throw(exc)
  File "/home/python/Desktop/spider3/ProxyPool/proxypool/tester.py", line 44, in test_single_proxy
    self.redis.decrease(proxy)
  File "/home/python/Desktop/spider3/ProxyPool/proxypool/db.py", line 77, in decrease
    logger.info('代理%s, 当前分数%d移除' % (proxy, score))
TypeError: %d format: a number is required, not NoneType
2018-09-21 18:53:09,715 - asyncio - ERROR - Task exception was never retrieved
future: <Task finished coro=<Tester.test_single_proxy() done, defined at /home/python/Desktop/spider3/ProxyPool/proxypool/tester.py:20> exception=TypeError('%d format: a number is required, not NoneType',)>
Traceback (most recent call last):
  File "/home/python/Desktop/spider3/ProxyPool/proxypool/tester.py", line 35, in test_single_proxy
    async with session.get(TEST_URL, proxy=real_proxy, timeout=5, allow_redirects=False) as response:
  File "/home/python/.virtualenvs/Env1/lib/python3.5/site-packages/aiohttp/client.py", line 690, in __aenter__
    self._resp = yield from self._coro
  File "/home/python/.virtualenvs/Env1/lib/python3.5/site-packages/aiohttp/client.py", line 341, in _request
    break
  File "/home/python/.virtualenvs/Env1/lib/python3.5/site-packages/aiohttp/helpers.py", line 732, in __exit__
    raise asyncio.TimeoutError from None
concurrent.futures._base.TimeoutError

During handling of the above exception, another exception occurred:

Traceback (most recent call last):
  File "/usr/lib/python3.5/asyncio/tasks.py", line 241, in _step
    result = coro.throw(exc)
  File "/home/python/Desktop/spider3/ProxyPool/proxypool/tester.py", line 44, in test_single_proxy
    self.redis.decrease(proxy)
  File "/home/python/Desktop/spider3/ProxyPool/proxypool/db.py", line 77, in decrease
    logger.info('代理%s, 当前分数%d移除' % (proxy, score))
TypeError: %d format: a number is required, not NoneType
2018-09-21 18:53:09,716 - asyncio - ERROR - Task exception was never retrieved
future: <Task finished coro=<Tester.test_single_proxy() done, defined at /home/python/Desktop/spider3/ProxyPool/proxypool/tester.py:20> exception=TypeError('%d format: a number is required, not NoneType',)>
Traceback (most recent call last):
  File "/home/python/Desktop/spider3/ProxyPool/proxypool/tester.py", line 35, in test_single_proxy
    async with session.get(TEST_URL, proxy=real_proxy, timeout=5, allow_redirects=False) as response:
  File "/home/python/.virtualenvs/Env1/lib/python3.5/site-packages/aiohttp/client.py", line 690, in __aenter__
    self._resp = yield from self._coro
  File "/home/python/.virtualenvs/Env1/lib/python3.5/site-packages/aiohttp/client.py", line 341, in _request
    break
  File "/home/python/.virtualenvs/Env1/lib/python3.5/site-packages/aiohttp/helpers.py", line 732, in __exit__
    raise asyncio.TimeoutError from None
concurrent.futures._base.TimeoutError

During handling of the above exception, another exception occurred:

Traceback (most recent call last):
  File "/usr/lib/python3.5/asyncio/tasks.py", line 241, in _step
    result = coro.throw(exc)
  File "/home/python/Desktop/spider3/ProxyPool/proxypool/tester.py", line 44, in test_single_proxy
    self.redis.decrease(proxy)
  File "/home/python/Desktop/spider3/ProxyPool/proxypool/db.py", line 77, in decrease
    logger.info('代理%s, 当前分数%d移除' % (proxy, score))
TypeError: %d format: a number is required, not NoneType
2018-09-21 18:53:09,716 - asyncio - ERROR - Task exception was never retrieved
future: <Task finished coro=<Tester.test_single_proxy() done, defined at /home/python/Desktop/spider3/ProxyPool/proxypool/tester.py:20> exception=TypeError('%d format: a number is required, not NoneType',)>
Traceback (most recent call last):
  File "/home/python/Desktop/spider3/ProxyPool/proxypool/tester.py", line 35, in test_single_proxy
    async with session.get(TEST_URL, proxy=real_proxy, timeout=5, allow_redirects=False) as response:
  File "/home/python/.virtualenvs/Env1/lib/python3.5/site-packages/aiohttp/client.py", line 690, in __aenter__
    self._resp = yield from self._coro
  File "/home/python/.virtualenvs/Env1/lib/python3.5/site-packages/aiohttp/client.py", line 341, in _request
    break
  File "/home/python/.virtualenvs/Env1/lib/python3.5/site-packages/aiohttp/helpers.py", line 732, in __exit__
    raise asyncio.TimeoutError from None
concurrent.futures._base.TimeoutError

During handling of the above exception, another exception occurred:

Traceback (most recent call last):
  File "/usr/lib/python3.5/asyncio/tasks.py", line 241, in _step
    result = coro.throw(exc)
  File "/home/python/Desktop/spider3/ProxyPool/proxypool/tester.py", line 44, in test_single_proxy
    self.redis.decrease(proxy)
  File "/home/python/Desktop/spider3/ProxyPool/proxypool/db.py", line 77, in decrease
    logger.info('代理%s, 当前分数%d移除' % (proxy, score))
TypeError: %d format: a number is required, not NoneType
2018-09-21 18:53:09,716 - asyncio - ERROR - Task exception was never retrieved
future: <Task finished coro=<Tester.test_single_proxy() done, defined at /home/python/Desktop/spider3/ProxyPool/proxypool/tester.py:20> exception=TypeError('%d format: a number is required, not NoneType',)>
Traceback (most recent call last):
  File "/home/python/Desktop/spider3/ProxyPool/proxypool/tester.py", line 35, in test_single_proxy
    async with session.get(TEST_URL, proxy=real_proxy, timeout=5, allow_redirects=False) as response:
  File "/home/python/.virtualenvs/Env1/lib/python3.5/site-packages/aiohttp/client.py", line 690, in __aenter__
    self._resp = yield from self._coro
  File "/home/python/.virtualenvs/Env1/lib/python3.5/site-packages/aiohttp/client.py", line 341, in _request
    break
  File "/home/python/.virtualenvs/Env1/lib/python3.5/site-packages/aiohttp/helpers.py", line 732, in __exit__
    raise asyncio.TimeoutError from None
concurrent.futures._base.TimeoutError

During handling of the above exception, another exception occurred:

Traceback (most recent call last):
  File "/usr/lib/python3.5/asyncio/tasks.py", line 241, in _step
    result = coro.throw(exc)
  File "/home/python/Desktop/spider3/ProxyPool/proxypool/tester.py", line 44, in test_single_proxy
    self.redis.decrease(proxy)
  File "/home/python/Desktop/spider3/ProxyPool/proxypool/db.py", line 77, in decrease
    logger.info('代理%s, 当前分数%d移除' % (proxy, score))
TypeError: %d format: a number is required, not NoneType
2018-09-21 18:53:09,717 - asyncio - ERROR - Task exception was never retrieved
future: <Task finished coro=<Tester.test_single_proxy() done, defined at /home/python/Desktop/spider3/ProxyPool/proxypool/tester.py:20> exception=TypeError('%d format: a number is required, not NoneType',)>
Traceback (most recent call last):
  File "/home/python/Desktop/spider3/ProxyPool/proxypool/tester.py", line 35, in test_single_proxy
    async with session.get(TEST_URL, proxy=real_proxy, timeout=5, allow_redirects=False) as response:
  File "/home/python/.virtualenvs/Env1/lib/python3.5/site-packages/aiohttp/client.py", line 690, in __aenter__
    self._resp = yield from self._coro
  File "/home/python/.virtualenvs/Env1/lib/python3.5/site-packages/aiohttp/client.py", line 341, in _request
    break
  File "/home/python/.virtualenvs/Env1/lib/python3.5/site-packages/aiohttp/helpers.py", line 732, in __exit__
    raise asyncio.TimeoutError from None
concurrent.futures._base.TimeoutError

During handling of the above exception, another exception occurred:

Traceback (most recent call last):
  File "/usr/lib/python3.5/asyncio/tasks.py", line 241, in _step
    result = coro.throw(exc)
  File "/home/python/Desktop/spider3/ProxyPool/proxypool/tester.py", line 44, in test_single_proxy
    self.redis.decrease(proxy)
  File "/home/python/Desktop/spider3/ProxyPool/proxypool/db.py", line 77, in decrease
    logger.info('代理%s, 当前分数%d移除' % (proxy, score))
TypeError: %d format: a number is required, not NoneType
2018-09-21 18:53:09,717 - asyncio - ERROR - Task exception was never retrieved
future: <Task finished coro=<Tester.test_single_proxy() done, defined at /home/python/Desktop/spider3/ProxyPool/proxypool/tester.py:20> exception=TypeError('%d format: a number is required, not NoneType',)>
Traceback (most recent call last):
  File "/home/python/Desktop/spider3/ProxyPool/proxypool/tester.py", line 35, in test_single_proxy
    async with session.get(TEST_URL, proxy=real_proxy, timeout=5, allow_redirects=False) as response:
  File "/home/python/.virtualenvs/Env1/lib/python3.5/site-packages/aiohttp/client.py", line 690, in __aenter__
    self._resp = yield from self._coro
  File "/home/python/.virtualenvs/Env1/lib/python3.5/site-packages/aiohttp/client.py", line 341, in _request
    break
  File "/home/python/.virtualenvs/Env1/lib/python3.5/site-packages/aiohttp/helpers.py", line 732, in __exit__
    raise asyncio.TimeoutError from None
concurrent.futures._base.TimeoutError

During handling of the above exception, another exception occurred:

Traceback (most recent call last):
  File "/usr/lib/python3.5/asyncio/tasks.py", line 241, in _step
    result = coro.throw(exc)
  File "/home/python/Desktop/spider3/ProxyPool/proxypool/tester.py", line 44, in test_single_proxy
    self.redis.decrease(proxy)
  File "/home/python/Desktop/spider3/ProxyPool/proxypool/db.py", line 77, in decrease
    logger.info('代理%s, 当前分数%d移除' % (proxy, score))
TypeError: %d format: a number is required, not NoneType
2018-09-21 18:53:09,718 - asyncio - ERROR - Task exception was never retrieved
future: <Task finished coro=<Tester.test_single_proxy() done, defined at /home/python/Desktop/spider3/ProxyPool/proxypool/tester.py:20> exception=TypeError('%d format: a number is required, not NoneType',)>
Traceback (most recent call last):
  File "/home/python/Desktop/spider3/ProxyPool/proxypool/tester.py", line 35, in test_single_proxy
    async with session.get(TEST_URL, proxy=real_proxy, timeout=5, allow_redirects=False) as response:
  File "/home/python/.virtualenvs/Env1/lib/python3.5/site-packages/aiohttp/client.py", line 690, in __aenter__
    self._resp = yield from self._coro
  File "/home/python/.virtualenvs/Env1/lib/python3.5/site-packages/aiohttp/client.py", line 341, in _request
    break
  File "/home/python/.virtualenvs/Env1/lib/python3.5/site-packages/aiohttp/helpers.py", line 732, in __exit__
    raise asyncio.TimeoutError from None
concurrent.futures._base.TimeoutError

During handling of the above exception, another exception occurred:

Traceback (most recent call last):
  File "/usr/lib/python3.5/asyncio/tasks.py", line 241, in _step
    result = coro.throw(exc)
  File "/home/python/Desktop/spider3/ProxyPool/proxypool/tester.py", line 44, in test_single_proxy
    self.redis.decrease(proxy)
  File "/home/python/Desktop/spider3/ProxyPool/proxypool/db.py", line 77, in decrease
    logger.info('代理%s, 当前分数%d移除' % (proxy, score))
TypeError: %d format: a number is required, not NoneType
2018-09-21 18:53:09,718 - asyncio - ERROR - Task exception was never retrieved
future: <Task finished coro=<Tester.test_single_proxy() done, defined at /home/python/Desktop/spider3/ProxyPool/proxypool/tester.py:20> exception=TypeError('%d format: a number is required, not NoneType',)>
Traceback (most recent call last):
  File "/home/python/Desktop/spider3/ProxyPool/proxypool/tester.py", line 35, in test_single_proxy
    async with session.get(TEST_URL, proxy=real_proxy, timeout=5, allow_redirects=False) as response:
  File "/home/python/.virtualenvs/Env1/lib/python3.5/site-packages/aiohttp/client.py", line 690, in __aenter__
    self._resp = yield from self._coro
  File "/home/python/.virtualenvs/Env1/lib/python3.5/site-packages/aiohttp/client.py", line 341, in _request
    break
  File "/home/python/.virtualenvs/Env1/lib/python3.5/site-packages/aiohttp/helpers.py", line 732, in __exit__
    raise asyncio.TimeoutError from None
concurrent.futures._base.TimeoutError

During handling of the above exception, another exception occurred:

Traceback (most recent call last):
  File "/usr/lib/python3.5/asyncio/tasks.py", line 241, in _step
    result = coro.throw(exc)
  File "/home/python/Desktop/spider3/ProxyPool/proxypool/tester.py", line 44, in test_single_proxy
    self.redis.decrease(proxy)
  File "/home/python/Desktop/spider3/ProxyPool/proxypool/db.py", line 77, in decrease
    logger.info('代理%s, 当前分数%d移除' % (proxy, score))
TypeError: %d format: a number is required, not NoneType
2018-09-21 18:53:09,719 - asyncio - ERROR - Task exception was never retrieved
future: <Task finished coro=<Tester.test_single_proxy() done, defined at /home/python/Desktop/spider3/ProxyPool/proxypool/tester.py:20> exception=TypeError('%d format: a number is required, not NoneType',)>
Traceback (most recent call last):
  File "/home/python/Desktop/spider3/ProxyPool/proxypool/tester.py", line 35, in test_single_proxy
    async with session.get(TEST_URL, proxy=real_proxy, timeout=5, allow_redirects=False) as response:
  File "/home/python/.virtualenvs/Env1/lib/python3.5/site-packages/aiohttp/client.py", line 690, in __aenter__
    self._resp = yield from self._coro
  File "/home/python/.virtualenvs/Env1/lib/python3.5/site-packages/aiohttp/client.py", line 341, in _request
    break
  File "/home/python/.virtualenvs/Env1/lib/python3.5/site-packages/aiohttp/helpers.py", line 732, in __exit__
    raise asyncio.TimeoutError from None
concurrent.futures._base.TimeoutError

During handling of the above exception, another exception occurred:

Traceback (most recent call last):
  File "/usr/lib/python3.5/asyncio/tasks.py", line 241, in _step
    result = coro.throw(exc)
  File "/home/python/Desktop/spider3/ProxyPool/proxypool/tester.py", line 44, in test_single_proxy
    self.redis.decrease(proxy)
  File "/home/python/Desktop/spider3/ProxyPool/proxypool/db.py", line 77, in decrease
    logger.info('代理%s, 当前分数%d移除' % (proxy, score))
TypeError: %d format: a number is required, not NoneType
2018-09-21 18:53:09,719 - asyncio - ERROR - Task exception was never retrieved
future: <Task finished coro=<Tester.test_single_proxy() done, defined at /home/python/Desktop/spider3/ProxyPool/proxypool/tester.py:20> exception=TypeError('%d format: a number is required, not NoneType',)>
Traceback (most recent call last):
  File "/home/python/Desktop/spider3/ProxyPool/proxypool/tester.py", line 35, in test_single_proxy
    async with session.get(TEST_URL, proxy=real_proxy, timeout=5, allow_redirects=False) as response:
  File "/home/python/.virtualenvs/Env1/lib/python3.5/site-packages/aiohttp/client.py", line 690, in __aenter__
    self._resp = yield from self._coro
  File "/home/python/.virtualenvs/Env1/lib/python3.5/site-packages/aiohttp/client.py", line 341, in _request
    break
  File "/home/python/.virtualenvs/Env1/lib/python3.5/site-packages/aiohttp/helpers.py", line 732, in __exit__
    raise asyncio.TimeoutError from None
concurrent.futures._base.TimeoutError

During handling of the above exception, another exception occurred:

Traceback (most recent call last):
  File "/usr/lib/python3.5/asyncio/tasks.py", line 241, in _step
    result = coro.throw(exc)
  File "/home/python/Desktop/spider3/ProxyPool/proxypool/tester.py", line 44, in test_single_proxy
    self.redis.decrease(proxy)
  File "/home/python/Desktop/spider3/ProxyPool/proxypool/db.py", line 77, in decrease
    logger.info('代理%s, 当前分数%d移除' % (proxy, score))
TypeError: %d format: a number is required, not NoneType
2018-09-21 18:53:09,720 - asyncio - ERROR - Task exception was never retrieved
future: <Task finished coro=<Tester.test_single_proxy() done, defined at /home/python/Desktop/spider3/ProxyPool/proxypool/tester.py:20> exception=TypeError('%d format: a number is required, not NoneType',)>
Traceback (most recent call last):
  File "/home/python/Desktop/spider3/ProxyPool/proxypool/tester.py", line 35, in test_single_proxy
    async with session.get(TEST_URL, proxy=real_proxy, timeout=5, allow_redirects=False) as response:
  File "/home/python/.virtualenvs/Env1/lib/python3.5/site-packages/aiohttp/client.py", line 690, in __aenter__
    self._resp = yield from self._coro
  File "/home/python/.virtualenvs/Env1/lib/python3.5/site-packages/aiohttp/client.py", line 267, in _request
    conn = yield from self._connector.connect(req)
  File "/home/python/.virtualenvs/Env1/lib/python3.5/site-packages/aiohttp/connector.py", line 402, in connect
    proto = yield from self._create_connection(req)
  File "/home/python/.virtualenvs/Env1/lib/python3.5/site-packages/aiohttp/connector.py", line 747, in _create_connection
    _, proto = yield from self._create_proxy_connection(req)
  File "/home/python/.virtualenvs/Env1/lib/python3.5/site-packages/aiohttp/connector.py", line 906, in _create_proxy_connection
    resp = yield from proxy_resp.start(conn, True)
  File "/home/python/.virtualenvs/Env1/lib/python3.5/site-packages/aiohttp/client_reqrep.py", line 624, in start
    (message, payload) = yield from self._protocol.read()
  File "/home/python/.virtualenvs/Env1/lib/python3.5/site-packages/aiohttp/streams.py", line 554, in read
    yield from self._waiter
  File "/usr/lib/python3.5/asyncio/futures.py", line 361, in __iter__
    yield self  # This tells Task to wait for completion.
  File "/usr/lib/python3.5/asyncio/tasks.py", line 296, in _wakeup
    future.result()
  File "/usr/lib/python3.5/asyncio/futures.py", line 274, in result
    raise self._exception
aiohttp.client_exceptions.ServerDisconnectedError

During handling of the above exception, another exception occurred:

Traceback (most recent call last):
  File "/usr/lib/python3.5/asyncio/tasks.py", line 241, in _step
    result = coro.throw(exc)
  File "/home/python/Desktop/spider3/ProxyPool/proxypool/tester.py", line 44, in test_single_proxy
    self.redis.decrease(proxy)
  File "/home/python/Desktop/spider3/ProxyPool/proxypool/db.py", line 77, in decrease
    logger.info('代理%s, 当前分数%d移除' % (proxy, score))
TypeError: %d format: a number is required, not NoneType
2018-09-21 18:53:09,720 - asyncio - ERROR - Task exception was never retrieved
future: <Task finished coro=<Tester.test_single_proxy() done, defined at /home/python/Desktop/spider3/ProxyPool/proxypool/tester.py:20> exception=TypeError('%d format: a number is required, not NoneType',)>
Traceback (most recent call last):
  File "/home/python/Desktop/spider3/ProxyPool/proxypool/tester.py", line 35, in test_single_proxy
    async with session.get(TEST_URL, proxy=real_proxy, timeout=5, allow_redirects=False) as response:
  File "/home/python/.virtualenvs/Env1/lib/python3.5/site-packages/aiohttp/client.py", line 690, in __aenter__
    self._resp = yield from self._coro
  File "/home/python/.virtualenvs/Env1/lib/python3.5/site-packages/aiohttp/client.py", line 341, in _request
    break
  File "/home/python/.virtualenvs/Env1/lib/python3.5/site-packages/aiohttp/helpers.py", line 732, in __exit__
    raise asyncio.TimeoutError from None
concurrent.futures._base.TimeoutError

During handling of the above exception, another exception occurred:

Traceback (most recent call last):
  File "/usr/lib/python3.5/asyncio/tasks.py", line 241, in _step
    result = coro.throw(exc)
  File "/home/python/Desktop/spider3/ProxyPool/proxypool/tester.py", line 44, in test_single_proxy
    self.redis.decrease(proxy)
  File "/home/python/Desktop/spider3/ProxyPool/proxypool/db.py", line 77, in decrease
    logger.info('代理%s, 当前分数%d移除' % (proxy, score))
TypeError: %d format: a number is required, not NoneType
2018-09-21 18:53:09,720 - asyncio - ERROR - Task exception was never retrieved
future: <Task finished coro=<Tester.test_single_proxy() done, defined at /home/python/Desktop/spider3/ProxyPool/proxypool/tester.py:20> exception=TypeError('%d format: a number is required, not NoneType',)>
Traceback (most recent call last):
  File "/home/python/Desktop/spider3/ProxyPool/proxypool/tester.py", line 35, in test_single_proxy
    async with session.get(TEST_URL, proxy=real_proxy, timeout=5, allow_redirects=False) as response:
  File "/home/python/.virtualenvs/Env1/lib/python3.5/site-packages/aiohttp/client.py", line 690, in __aenter__
    self._resp = yield from self._coro
  File "/home/python/.virtualenvs/Env1/lib/python3.5/site-packages/aiohttp/client.py", line 341, in _request
    break
  File "/home/python/.virtualenvs/Env1/lib/python3.5/site-packages/aiohttp/helpers.py", line 732, in __exit__
    raise asyncio.TimeoutError from None
concurrent.futures._base.TimeoutError

During handling of the above exception, another exception occurred:

Traceback (most recent call last):
  File "/usr/lib/python3.5/asyncio/tasks.py", line 241, in _step
    result = coro.throw(exc)
  File "/home/python/Desktop/spider3/ProxyPool/proxypool/tester.py", line 44, in test_single_proxy
    self.redis.decrease(proxy)
  File "/home/python/Desktop/spider3/ProxyPool/proxypool/db.py", line 77, in decrease
    logger.info('代理%s, 当前分数%d移除' % (proxy, score))
TypeError: %d format: a number is required, not NoneType
2018-09-21 18:53:09,721 - asyncio - ERROR - Task exception was never retrieved
future: <Task finished coro=<Tester.test_single_proxy() done, defined at /home/python/Desktop/spider3/ProxyPool/proxypool/tester.py:20> exception=TypeError('%d format: a number is required, not NoneType',)>
Traceback (most recent call last):
  File "/home/python/Desktop/spider3/ProxyPool/proxypool/tester.py", line 35, in test_single_proxy
    async with session.get(TEST_URL, proxy=real_proxy, timeout=5, allow_redirects=False) as response:
  File "/home/python/.virtualenvs/Env1/lib/python3.5/site-packages/aiohttp/client.py", line 690, in __aenter__
    self._resp = yield from self._coro
  File "/home/python/.virtualenvs/Env1/lib/python3.5/site-packages/aiohttp/client.py", line 341, in _request
    break
  File "/home/python/.virtualenvs/Env1/lib/python3.5/site-packages/aiohttp/helpers.py", line 732, in __exit__
    raise asyncio.TimeoutError from None
concurrent.futures._base.TimeoutError

During handling of the above exception, another exception occurred:

Traceback (most recent call last):
  File "/usr/lib/python3.5/asyncio/tasks.py", line 241, in _step
    result = coro.throw(exc)
  File "/home/python/Desktop/spider3/ProxyPool/proxypool/tester.py", line 44, in test_single_proxy
    self.redis.decrease(proxy)
  File "/home/python/Desktop/spider3/ProxyPool/proxypool/db.py", line 77, in decrease
    logger.info('代理%s, 当前分数%d移除' % (proxy, score))
TypeError: %d format: a number is required, not NoneType
2018-09-21 18:53:09,721 - asyncio - ERROR - Task exception was never retrieved
future: <Task finished coro=<Tester.test_single_proxy() done, defined at /home/python/Desktop/spider3/ProxyPool/proxypool/tester.py:20> exception=TypeError('%d format: a number is required, not NoneType',)>
Traceback (most recent call last):
  File "/home/python/Desktop/spider3/ProxyPool/proxypool/tester.py", line 35, in test_single_proxy
    async with session.get(TEST_URL, proxy=real_proxy, timeout=5, allow_redirects=False) as response:
  File "/home/python/.virtualenvs/Env1/lib/python3.5/site-packages/aiohttp/client.py", line 690, in __aenter__
    self._resp = yield from self._coro
  File "/home/python/.virtualenvs/Env1/lib/python3.5/site-packages/aiohttp/client.py", line 341, in _request
    break
  File "/home/python/.virtualenvs/Env1/lib/python3.5/site-packages/aiohttp/helpers.py", line 732, in __exit__
    raise asyncio.TimeoutError from None
concurrent.futures._base.TimeoutError

During handling of the above exception, another exception occurred:

Traceback (most recent call last):
  File "/usr/lib/python3.5/asyncio/tasks.py", line 241, in _step
    result = coro.throw(exc)
  File "/home/python/Desktop/spider3/ProxyPool/proxypool/tester.py", line 44, in test_single_proxy
    self.redis.decrease(proxy)
  File "/home/python/Desktop/spider3/ProxyPool/proxypool/db.py", line 77, in decrease
    logger.info('代理%s, 当前分数%d移除' % (proxy, score))
TypeError: %d format: a number is required, not NoneType
2018-09-21 18:53:09,722 - asyncio - ERROR - Task exception was never retrieved
future: <Task finished coro=<Tester.test_single_proxy() done, defined at /home/python/Desktop/spider3/ProxyPool/proxypool/tester.py:20> exception=TypeError('%d format: a number is required, not NoneType',)>
Traceback (most recent call last):
  File "/home/python/Desktop/spider3/ProxyPool/proxypool/tester.py", line 35, in test_single_proxy
    async with session.get(TEST_URL, proxy=real_proxy, timeout=5, allow_redirects=False) as response:
  File "/home/python/.virtualenvs/Env1/lib/python3.5/site-packages/aiohttp/client.py", line 690, in __aenter__
    self._resp = yield from self._coro
  File "/home/python/.virtualenvs/Env1/lib/python3.5/site-packages/aiohttp/client.py", line 341, in _request
    break
  File "/home/python/.virtualenvs/Env1/lib/python3.5/site-packages/aiohttp/helpers.py", line 732, in __exit__
    raise asyncio.TimeoutError from None
concurrent.futures._base.TimeoutError

During handling of the above exception, another exception occurred:

Traceback (most recent call last):
  File "/usr/lib/python3.5/asyncio/tasks.py", line 241, in _step
    result = coro.throw(exc)
  File "/home/python/Desktop/spider3/ProxyPool/proxypool/tester.py", line 44, in test_single_proxy
    self.redis.decrease(proxy)
  File "/home/python/Desktop/spider3/ProxyPool/proxypool/db.py", line 77, in decrease
    logger.info('代理%s, 当前分数%d移除' % (proxy, score))
TypeError: %d format: a number is required, not NoneType
2018-09-21 18:53:09,722 - asyncio - ERROR - Task exception was never retrieved
future: <Task finished coro=<Tester.test_single_proxy() done, defined at /home/python/Desktop/spider3/ProxyPool/proxypool/tester.py:20> exception=TypeError('%d format: a number is required, not NoneType',)>
Traceback (most recent call last):
  File "/home/python/Desktop/spider3/ProxyPool/proxypool/tester.py", line 35, in test_single_proxy
    async with session.get(TEST_URL, proxy=real_proxy, timeout=5, allow_redirects=False) as response:
  File "/home/python/.virtualenvs/Env1/lib/python3.5/site-packages/aiohttp/client.py", line 690, in __aenter__
    self._resp = yield from self._coro
  File "/home/python/.virtualenvs/Env1/lib/python3.5/site-packages/aiohttp/client.py", line 341, in _request
    break
  File "/home/python/.virtualenvs/Env1/lib/python3.5/site-packages/aiohttp/helpers.py", line 732, in __exit__
    raise asyncio.TimeoutError from None
concurrent.futures._base.TimeoutError

During handling of the above exception, another exception occurred:

Traceback (most recent call last):
  File "/usr/lib/python3.5/asyncio/tasks.py", line 241, in _step
    result = coro.throw(exc)
  File "/home/python/Desktop/spider3/ProxyPool/proxypool/tester.py", line 44, in test_single_proxy
    self.redis.decrease(proxy)
  File "/home/python/Desktop/spider3/ProxyPool/proxypool/db.py", line 77, in decrease
    logger.info('代理%s, 当前分数%d移除' % (proxy, score))
TypeError: %d format: a number is required, not NoneType
2018-09-21 18:53:09,723 - asyncio - ERROR - Task exception was never retrieved
future: <Task finished coro=<Tester.test_single_proxy() done, defined at /home/python/Desktop/spider3/ProxyPool/proxypool/tester.py:20> exception=TypeError('%d format: a number is required, not NoneType',)>
Traceback (most recent call last):
  File "/home/python/Desktop/spider3/ProxyPool/proxypool/tester.py", line 35, in test_single_proxy
    async with session.get(TEST_URL, proxy=real_proxy, timeout=5, allow_redirects=False) as response:
  File "/home/python/.virtualenvs/Env1/lib/python3.5/site-packages/aiohttp/client.py", line 690, in __aenter__
    self._resp = yield from self._coro
  File "/home/python/.virtualenvs/Env1/lib/python3.5/site-packages/aiohttp/client.py", line 267, in _request
    conn = yield from self._connector.connect(req)
  File "/home/python/.virtualenvs/Env1/lib/python3.5/site-packages/aiohttp/connector.py", line 402, in connect
    proto = yield from self._create_connection(req)
  File "/home/python/.virtualenvs/Env1/lib/python3.5/site-packages/aiohttp/connector.py", line 747, in _create_connection
    _, proto = yield from self._create_proxy_connection(req)
  File "/home/python/.virtualenvs/Env1/lib/python3.5/site-packages/aiohttp/connector.py", line 906, in _create_proxy_connection
    resp = yield from proxy_resp.start(conn, True)
  File "/home/python/.virtualenvs/Env1/lib/python3.5/site-packages/aiohttp/client_reqrep.py", line 624, in start
    (message, payload) = yield from self._protocol.read()
  File "/home/python/.virtualenvs/Env1/lib/python3.5/site-packages/aiohttp/streams.py", line 554, in read
    yield from self._waiter
  File "/usr/lib/python3.5/asyncio/futures.py", line 361, in __iter__
    yield self  # This tells Task to wait for completion.
  File "/usr/lib/python3.5/asyncio/tasks.py", line 296, in _wakeup
    future.result()
  File "/usr/lib/python3.5/asyncio/futures.py", line 274, in result
    raise self._exception
aiohttp.client_exceptions.ClientOSError: [Errno 104] Connection reset by peer

During handling of the above exception, another exception occurred:

Traceback (most recent call last):
  File "/usr/lib/python3.5/asyncio/tasks.py", line 241, in _step
    result = coro.throw(exc)
  File "/home/python/Desktop/spider3/ProxyPool/proxypool/tester.py", line 44, in test_single_proxy
    self.redis.decrease(proxy)
  File "/home/python/Desktop/spider3/ProxyPool/proxypool/db.py", line 77, in decrease
    logger.info('代理%s, 当前分数%d移除' % (proxy, score))
TypeError: %d format: a number is required, not NoneType
2018-09-21 18:53:09,723 - asyncio - ERROR - Task exception was never retrieved
future: <Task finished coro=<Tester.test_single_proxy() done, defined at /home/python/Desktop/spider3/ProxyPool/proxypool/tester.py:20> exception=TypeError('%d format: a number is required, not NoneType',)>
Traceback (most recent call last):
  File "/home/python/Desktop/spider3/ProxyPool/proxypool/tester.py", line 35, in test_single_proxy
    async with session.get(TEST_URL, proxy=real_proxy, timeout=5, allow_redirects=False) as response:
  File "/home/python/.virtualenvs/Env1/lib/python3.5/site-packages/aiohttp/client.py", line 690, in __aenter__
    self._resp = yield from self._coro
  File "/home/python/.virtualenvs/Env1/lib/python3.5/site-packages/aiohttp/client.py", line 341, in _request
    break
  File "/home/python/.virtualenvs/Env1/lib/python3.5/site-packages/aiohttp/helpers.py", line 732, in __exit__
    raise asyncio.TimeoutError from None
concurrent.futures._base.TimeoutError

During handling of the above exception, another exception occurred:

Traceback (most recent call last):
  File "/usr/lib/python3.5/asyncio/tasks.py", line 241, in _step
    result = coro.throw(exc)
  File "/home/python/Desktop/spider3/ProxyPool/proxypool/tester.py", line 44, in test_single_proxy
    self.redis.decrease(proxy)
  File "/home/python/Desktop/spider3/ProxyPool/proxypool/db.py", line 77, in decrease
    logger.info('代理%s, 当前分数%d移除' % (proxy, score))
TypeError: %d format: a number is required, not NoneType
2018-09-21 18:53:09,723 - asyncio - ERROR - Task exception was never retrieved
future: <Task finished coro=<Tester.test_single_proxy() done, defined at /home/python/Desktop/spider3/ProxyPool/proxypool/tester.py:20> exception=TypeError('%d format: a number is required, not NoneType',)>
Traceback (most recent call last):
  File "/home/python/Desktop/spider3/ProxyPool/proxypool/tester.py", line 35, in test_single_proxy
    async with session.get(TEST_URL, proxy=real_proxy, timeout=5, allow_redirects=False) as response:
  File "/home/python/.virtualenvs/Env1/lib/python3.5/site-packages/aiohttp/client.py", line 690, in __aenter__
    self._resp = yield from self._coro
  File "/home/python/.virtualenvs/Env1/lib/python3.5/site-packages/aiohttp/client.py", line 341, in _request
    break
  File "/home/python/.virtualenvs/Env1/lib/python3.5/site-packages/aiohttp/helpers.py", line 732, in __exit__
    raise asyncio.TimeoutError from None
concurrent.futures._base.TimeoutError

During handling of the above exception, another exception occurred:

Traceback (most recent call last):
  File "/usr/lib/python3.5/asyncio/tasks.py", line 241, in _step
    result = coro.throw(exc)
  File "/home/python/Desktop/spider3/ProxyPool/proxypool/tester.py", line 44, in test_single_proxy
    self.redis.decrease(proxy)
  File "/home/python/Desktop/spider3/ProxyPool/proxypool/db.py", line 77, in decrease
    logger.info('代理%s, 当前分数%d移除' % (proxy, score))
TypeError: %d format: a number is required, not NoneType
2018-09-21 18:53:09,724 - asyncio - ERROR - Task exception was never retrieved
future: <Task finished coro=<Tester.test_single_proxy() done, defined at /home/python/Desktop/spider3/ProxyPool/proxypool/tester.py:20> exception=TypeError('%d format: a number is required, not NoneType',)>
Traceback (most recent call last):
  File "/home/python/Desktop/spider3/ProxyPool/proxypool/tester.py", line 35, in test_single_proxy
    async with session.get(TEST_URL, proxy=real_proxy, timeout=5, allow_redirects=False) as response:
  File "/home/python/.virtualenvs/Env1/lib/python3.5/site-packages/aiohttp/client.py", line 690, in __aenter__
    self._resp = yield from self._coro
  File "/home/python/.virtualenvs/Env1/lib/python3.5/site-packages/aiohttp/client.py", line 341, in _request
    break
  File "/home/python/.virtualenvs/Env1/lib/python3.5/site-packages/aiohttp/helpers.py", line 732, in __exit__
    raise asyncio.TimeoutError from None
concurrent.futures._base.TimeoutError

During handling of the above exception, another exception occurred:

Traceback (most recent call last):
  File "/usr/lib/python3.5/asyncio/tasks.py", line 241, in _step
    result = coro.throw(exc)
  File "/home/python/Desktop/spider3/ProxyPool/proxypool/tester.py", line 44, in test_single_proxy
    self.redis.decrease(proxy)
  File "/home/python/Desktop/spider3/ProxyPool/proxypool/db.py", line 77, in decrease
    logger.info('代理%s, 当前分数%d移除' % (proxy, score))
TypeError: %d format: a number is required, not NoneType
2018-09-21 18:53:09,724 - asyncio - ERROR - Task exception was never retrieved
future: <Task finished coro=<Tester.test_single_proxy() done, defined at /home/python/Desktop/spider3/ProxyPool/proxypool/tester.py:20> exception=TypeError('%d format: a number is required, not NoneType',)>
Traceback (most recent call last):
  File "/home/python/Desktop/spider3/ProxyPool/proxypool/tester.py", line 35, in test_single_proxy
    async with session.get(TEST_URL, proxy=real_proxy, timeout=5, allow_redirects=False) as response:
  File "/home/python/.virtualenvs/Env1/lib/python3.5/site-packages/aiohttp/client.py", line 690, in __aenter__
    self._resp = yield from self._coro
  File "/home/python/.virtualenvs/Env1/lib/python3.5/site-packages/aiohttp/client.py", line 341, in _request
    break
  File "/home/python/.virtualenvs/Env1/lib/python3.5/site-packages/aiohttp/helpers.py", line 732, in __exit__
    raise asyncio.TimeoutError from None
concurrent.futures._base.TimeoutError

During handling of the above exception, another exception occurred:

Traceback (most recent call last):
  File "/usr/lib/python3.5/asyncio/tasks.py", line 241, in _step
    result = coro.throw(exc)
  File "/home/python/Desktop/spider3/ProxyPool/proxypool/tester.py", line 44, in test_single_proxy
    self.redis.decrease(proxy)
  File "/home/python/Desktop/spider3/ProxyPool/proxypool/db.py", line 77, in decrease
    logger.info('代理%s, 当前分数%d移除' % (proxy, score))
TypeError: %d format: a number is required, not NoneType
2018-09-21 18:53:09,725 - asyncio - ERROR - Task exception was never retrieved
future: <Task finished coro=<Tester.test_single_proxy() done, defined at /home/python/Desktop/spider3/ProxyPool/proxypool/tester.py:20> exception=TypeError('%d format: a number is required, not NoneType',)>
Traceback (most recent call last):
  File "/home/python/Desktop/spider3/ProxyPool/proxypool/tester.py", line 35, in test_single_proxy
    async with session.get(TEST_URL, proxy=real_proxy, timeout=5, allow_redirects=False) as response:
  File "/home/python/.virtualenvs/Env1/lib/python3.5/site-packages/aiohttp/client.py", line 690, in __aenter__
    self._resp = yield from self._coro
  File "/home/python/.virtualenvs/Env1/lib/python3.5/site-packages/aiohttp/client.py", line 341, in _request
    break
  File "/home/python/.virtualenvs/Env1/lib/python3.5/site-packages/aiohttp/helpers.py", line 732, in __exit__
    raise asyncio.TimeoutError from None
concurrent.futures._base.TimeoutError

During handling of the above exception, another exception occurred:

Traceback (most recent call last):
  File "/usr/lib/python3.5/asyncio/tasks.py", line 241, in _step
    result = coro.throw(exc)
  File "/home/python/Desktop/spider3/ProxyPool/proxypool/tester.py", line 44, in test_single_proxy
    self.redis.decrease(proxy)
  File "/home/python/Desktop/spider3/ProxyPool/proxypool/db.py", line 77, in decrease
    logger.info('代理%s, 当前分数%d移除' % (proxy, score))
TypeError: %d format: a number is required, not NoneType
2018-09-21 18:53:09,725 - asyncio - ERROR - Task exception was never retrieved
future: <Task finished coro=<Tester.test_single_proxy() done, defined at /home/python/Desktop/spider3/ProxyPool/proxypool/tester.py:20> exception=TypeError('%d format: a number is required, not NoneType',)>
Traceback (most recent call last):
  File "/home/python/Desktop/spider3/ProxyPool/proxypool/tester.py", line 35, in test_single_proxy
    async with session.get(TEST_URL, proxy=real_proxy, timeout=5, allow_redirects=False) as response:
  File "/home/python/.virtualenvs/Env1/lib/python3.5/site-packages/aiohttp/client.py", line 690, in __aenter__
    self._resp = yield from self._coro
  File "/home/python/.virtualenvs/Env1/lib/python3.5/site-packages/aiohttp/client.py", line 341, in _request
    break
  File "/home/python/.virtualenvs/Env1/lib/python3.5/site-packages/aiohttp/helpers.py", line 732, in __exit__
    raise asyncio.TimeoutError from None
concurrent.futures._base.TimeoutError

During handling of the above exception, another exception occurred:

Traceback (most recent call last):
  File "/usr/lib/python3.5/asyncio/tasks.py", line 241, in _step
    result = coro.throw(exc)
  File "/home/python/Desktop/spider3/ProxyPool/proxypool/tester.py", line 44, in test_single_proxy
    self.redis.decrease(proxy)
  File "/home/python/Desktop/spider3/ProxyPool/proxypool/db.py", line 77, in decrease
    logger.info('代理%s, 当前分数%d移除' % (proxy, score))
TypeError: %d format: a number is required, not NoneType
2018-09-21 18:53:09,725 - asyncio - ERROR - Task exception was never retrieved
future: <Task finished coro=<Tester.test_single_proxy() done, defined at /home/python/Desktop/spider3/ProxyPool/proxypool/tester.py:20> exception=TypeError('%d format: a number is required, not NoneType',)>
Traceback (most recent call last):
  File "/home/python/Desktop/spider3/ProxyPool/proxypool/tester.py", line 35, in test_single_proxy
    async with session.get(TEST_URL, proxy=real_proxy, timeout=5, allow_redirects=False) as response:
  File "/home/python/.virtualenvs/Env1/lib/python3.5/site-packages/aiohttp/client.py", line 690, in __aenter__
    self._resp = yield from self._coro
  File "/home/python/.virtualenvs/Env1/lib/python3.5/site-packages/aiohttp/client.py", line 341, in _request
    break
  File "/home/python/.virtualenvs/Env1/lib/python3.5/site-packages/aiohttp/helpers.py", line 732, in __exit__
    raise asyncio.TimeoutError from None
concurrent.futures._base.TimeoutError

During handling of the above exception, another exception occurred:

Traceback (most recent call last):
  File "/usr/lib/python3.5/asyncio/tasks.py", line 241, in _step
    result = coro.throw(exc)
  File "/home/python/Desktop/spider3/ProxyPool/proxypool/tester.py", line 44, in test_single_proxy
    self.redis.decrease(proxy)
  File "/home/python/Desktop/spider3/ProxyPool/proxypool/db.py", line 77, in decrease
    logger.info('代理%s, 当前分数%d移除' % (proxy, score))
TypeError: %d format: a number is required, not NoneType
2018-09-21 18:53:09,726 - asyncio - ERROR - Task exception was never retrieved
future: <Task finished coro=<Tester.test_single_proxy() done, defined at /home/python/Desktop/spider3/ProxyPool/proxypool/tester.py:20> exception=TypeError('%d format: a number is required, not NoneType',)>
Traceback (most recent call last):
  File "/home/python/Desktop/spider3/ProxyPool/proxypool/tester.py", line 35, in test_single_proxy
    async with session.get(TEST_URL, proxy=real_proxy, timeout=5, allow_redirects=False) as response:
  File "/home/python/.virtualenvs/Env1/lib/python3.5/site-packages/aiohttp/client.py", line 690, in __aenter__
    self._resp = yield from self._coro
  File "/home/python/.virtualenvs/Env1/lib/python3.5/site-packages/aiohttp/client.py", line 341, in _request
    break
  File "/home/python/.virtualenvs/Env1/lib/python3.5/site-packages/aiohttp/helpers.py", line 732, in __exit__
    raise asyncio.TimeoutError from None
concurrent.futures._base.TimeoutError

During handling of the above exception, another exception occurred:

Traceback (most recent call last):
  File "/usr/lib/python3.5/asyncio/tasks.py", line 241, in _step
    result = coro.throw(exc)
  File "/home/python/Desktop/spider3/ProxyPool/proxypool/tester.py", line 44, in test_single_proxy
    self.redis.decrease(proxy)
  File "/home/python/Desktop/spider3/ProxyPool/proxypool/db.py", line 77, in decrease
    logger.info('代理%s, 当前分数%d移除' % (proxy, score))
TypeError: %d format: a number is required, not NoneType
2018-09-21 18:53:09,726 - asyncio - ERROR - Task exception was never retrieved
future: <Task finished coro=<Tester.test_single_proxy() done, defined at /home/python/Desktop/spider3/ProxyPool/proxypool/tester.py:20> exception=TypeError('%d format: a number is required, not NoneType',)>
Traceback (most recent call last):
  File "/home/python/Desktop/spider3/ProxyPool/proxypool/tester.py", line 35, in test_single_proxy
    async with session.get(TEST_URL, proxy=real_proxy, timeout=5, allow_redirects=False) as response:
  File "/home/python/.virtualenvs/Env1/lib/python3.5/site-packages/aiohttp/client.py", line 690, in __aenter__
    self._resp = yield from self._coro
  File "/home/python/.virtualenvs/Env1/lib/python3.5/site-packages/aiohttp/client.py", line 341, in _request
    break
  File "/home/python/.virtualenvs/Env1/lib/python3.5/site-packages/aiohttp/helpers.py", line 732, in __exit__
    raise asyncio.TimeoutError from None
concurrent.futures._base.TimeoutError

During handling of the above exception, another exception occurred:

Traceback (most recent call last):
  File "/usr/lib/python3.5/asyncio/tasks.py", line 241, in _step
    result = coro.throw(exc)
  File "/home/python/Desktop/spider3/ProxyPool/proxypool/tester.py", line 44, in test_single_proxy
    self.redis.decrease(proxy)
  File "/home/python/Desktop/spider3/ProxyPool/proxypool/db.py", line 77, in decrease
    logger.info('代理%s, 当前分数%d移除' % (proxy, score))
TypeError: %d format: a number is required, not NoneType
2018-09-21 18:53:09,727 - asyncio - ERROR - Task exception was never retrieved
future: <Task finished coro=<Tester.test_single_proxy() done, defined at /home/python/Desktop/spider3/ProxyPool/proxypool/tester.py:20> exception=TypeError('%d format: a number is required, not NoneType',)>
Traceback (most recent call last):
  File "/home/python/Desktop/spider3/ProxyPool/proxypool/tester.py", line 35, in test_single_proxy
    async with session.get(TEST_URL, proxy=real_proxy, timeout=5, allow_redirects=False) as response:
  File "/home/python/.virtualenvs/Env1/lib/python3.5/site-packages/aiohttp/client.py", line 690, in __aenter__
    self._resp = yield from self._coro
  File "/home/python/.virtualenvs/Env1/lib/python3.5/site-packages/aiohttp/client.py", line 267, in _request
    conn = yield from self._connector.connect(req)
  File "/home/python/.virtualenvs/Env1/lib/python3.5/site-packages/aiohttp/connector.py", line 402, in connect
    proto = yield from self._create_connection(req)
  File "/home/python/.virtualenvs/Env1/lib/python3.5/site-packages/aiohttp/connector.py", line 747, in _create_connection
    _, proto = yield from self._create_proxy_connection(req)
  File "/home/python/.virtualenvs/Env1/lib/python3.5/site-packages/aiohttp/connector.py", line 906, in _create_proxy_connection
    resp = yield from proxy_resp.start(conn, True)
  File "/home/python/.virtualenvs/Env1/lib/python3.5/site-packages/aiohttp/client_reqrep.py", line 624, in start
    (message, payload) = yield from self._protocol.read()
  File "/home/python/.virtualenvs/Env1/lib/python3.5/site-packages/aiohttp/streams.py", line 554, in read
    yield from self._waiter
  File "/usr/lib/python3.5/asyncio/futures.py", line 361, in __iter__
    yield self  # This tells Task to wait for completion.
  File "/usr/lib/python3.5/asyncio/tasks.py", line 296, in _wakeup
    future.result()
  File "/usr/lib/python3.5/asyncio/futures.py", line 274, in result
    raise self._exception
aiohttp.client_exceptions.ClientOSError: [Errno 104] Connection reset by peer

During handling of the above exception, another exception occurred:

Traceback (most recent call last):
  File "/usr/lib/python3.5/asyncio/tasks.py", line 241, in _step
    result = coro.throw(exc)
  File "/home/python/Desktop/spider3/ProxyPool/proxypool/tester.py", line 44, in test_single_proxy
    self.redis.decrease(proxy)
  File "/home/python/Desktop/spider3/ProxyPool/proxypool/db.py", line 77, in decrease
    logger.info('代理%s, 当前分数%d移除' % (proxy, score))
TypeError: %d format: a number is required, not NoneType
2018-09-21 18:53:09,727 - asyncio - ERROR - Task exception was never retrieved
future: <Task finished coro=<Tester.test_single_proxy() done, defined at /home/python/Desktop/spider3/ProxyPool/proxypool/tester.py:20> exception=TypeError('%d format: a number is required, not NoneType',)>
Traceback (most recent call last):
  File "/home/python/Desktop/spider3/ProxyPool/proxypool/tester.py", line 35, in test_single_proxy
    async with session.get(TEST_URL, proxy=real_proxy, timeout=5, allow_redirects=False) as response:
  File "/home/python/.virtualenvs/Env1/lib/python3.5/site-packages/aiohttp/client.py", line 690, in __aenter__
    self._resp = yield from self._coro
  File "/home/python/.virtualenvs/Env1/lib/python3.5/site-packages/aiohttp/client.py", line 341, in _request
    break
  File "/home/python/.virtualenvs/Env1/lib/python3.5/site-packages/aiohttp/helpers.py", line 732, in __exit__
    raise asyncio.TimeoutError from None
concurrent.futures._base.TimeoutError

During handling of the above exception, another exception occurred:

Traceback (most recent call last):
  File "/usr/lib/python3.5/asyncio/tasks.py", line 241, in _step
    result = coro.throw(exc)
  File "/home/python/Desktop/spider3/ProxyPool/proxypool/tester.py", line 44, in test_single_proxy
    self.redis.decrease(proxy)
  File "/home/python/Desktop/spider3/ProxyPool/proxypool/db.py", line 77, in decrease
    logger.info('代理%s, 当前分数%d移除' % (proxy, score))
TypeError: %d format: a number is required, not NoneType
2018-09-21 18:53:09,757 - asyncio - ERROR - Task exception was never retrieved
future: <Task finished coro=<Tester.test_single_proxy() done, defined at /home/python/Desktop/spider3/ProxyPool/proxypool/tester.py:20> exception=TypeError('%d format: a number is required, not NoneType',)>
Traceback (most recent call last):
  File "/home/python/Desktop/spider3/ProxyPool/proxypool/tester.py", line 35, in test_single_proxy
    async with session.get(TEST_URL, proxy=real_proxy, timeout=5, allow_redirects=False) as response:
  File "/home/python/.virtualenvs/Env1/lib/python3.5/site-packages/aiohttp/client.py", line 690, in __aenter__
    self._resp = yield from self._coro
  File "/home/python/.virtualenvs/Env1/lib/python3.5/site-packages/aiohttp/client.py", line 341, in _request
    break
  File "/home/python/.virtualenvs/Env1/lib/python3.5/site-packages/aiohttp/helpers.py", line 732, in __exit__
    raise asyncio.TimeoutError from None
concurrent.futures._base.TimeoutError

During handling of the above exception, another exception occurred:

Traceback (most recent call last):
  File "/usr/lib/python3.5/asyncio/tasks.py", line 241, in _step
    result = coro.throw(exc)
  File "/home/python/Desktop/spider3/ProxyPool/proxypool/tester.py", line 44, in test_single_proxy
    self.redis.decrease(proxy)
  File "/home/python/Desktop/spider3/ProxyPool/proxypool/db.py", line 77, in decrease
    logger.info('代理%s, 当前分数%d移除' % (proxy, score))
TypeError: %d format: a number is required, not NoneType
2018-09-21 18:53:09,758 - asyncio - ERROR - Task exception was never retrieved
future: <Task finished coro=<Tester.test_single_proxy() done, defined at /home/python/Desktop/spider3/ProxyPool/proxypool/tester.py:20> exception=TypeError('%d format: a number is required, not NoneType',)>
Traceback (most recent call last):
  File "/home/python/Desktop/spider3/ProxyPool/proxypool/tester.py", line 35, in test_single_proxy
    async with session.get(TEST_URL, proxy=real_proxy, timeout=5, allow_redirects=False) as response:
  File "/home/python/.virtualenvs/Env1/lib/python3.5/site-packages/aiohttp/client.py", line 690, in __aenter__
    self._resp = yield from self._coro
  File "/home/python/.virtualenvs/Env1/lib/python3.5/site-packages/aiohttp/client.py", line 267, in _request
    conn = yield from self._connector.connect(req)
  File "/home/python/.virtualenvs/Env1/lib/python3.5/site-packages/aiohttp/connector.py", line 402, in connect
    proto = yield from self._create_connection(req)
  File "/home/python/.virtualenvs/Env1/lib/python3.5/site-packages/aiohttp/connector.py", line 747, in _create_connection
    _, proto = yield from self._create_proxy_connection(req)
  File "/home/python/.virtualenvs/Env1/lib/python3.5/site-packages/aiohttp/connector.py", line 921, in _create_proxy_connection
    headers=resp.headers)
aiohttp.client_exceptions.ClientHttpProxyError: 500, message='Internal Server Error'

During handling of the above exception, another exception occurred:

Traceback (most recent call last):
  File "/usr/lib/python3.5/asyncio/tasks.py", line 239, in _step
    result = coro.send(None)
  File "/home/python/Desktop/spider3/ProxyPool/proxypool/tester.py", line 44, in test_single_proxy
    self.redis.decrease(proxy)
  File "/home/python/Desktop/spider3/ProxyPool/proxypool/db.py", line 77, in decrease
    logger.info('代理%s, 当前分数%d移除' % (proxy, score))
TypeError: %d format: a number is required, not NoneType
2018-09-21 18:53:09,758 - asyncio - ERROR - Task exception was never retrieved
future: <Task finished coro=<Tester.test_single_proxy() done, defined at /home/python/Desktop/spider3/ProxyPool/proxypool/tester.py:20> exception=TypeError('%d format: a number is required, not NoneType',)>
Traceback (most recent call last):
  File "/home/python/.virtualenvs/Env1/lib/python3.5/site-packages/aiohttp/connector.py", line 797, in _wrap_create_connection
    return (yield from self._loop.create_connection(*args, **kwargs))
  File "/usr/lib/python3.5/asyncio/base_events.py", line 695, in create_connection
    raise exceptions[0]
  File "/usr/lib/python3.5/asyncio/base_events.py", line 682, in create_connection
    yield from self.sock_connect(sock, address)
  File "/usr/lib/python3.5/asyncio/selector_events.py", line 402, in sock_connect
    return (yield from fut)
  File "/usr/lib/python3.5/asyncio/futures.py", line 361, in __iter__
    yield self  # This tells Task to wait for completion.
  File "/usr/lib/python3.5/asyncio/tasks.py", line 296, in _wakeup
    future.result()
  File "/usr/lib/python3.5/asyncio/futures.py", line 274, in result
    raise self._exception
  File "/usr/lib/python3.5/asyncio/selector_events.py", line 432, in _sock_connect_cb
    raise OSError(err, 'Connect call failed %s' % (address,))
ConnectionRefusedError: [Errno 111] Connect call failed ('218.95.81.250', 9000)

The above exception was the direct cause of the following exception:

Traceback (most recent call last):
  File "/home/python/Desktop/spider3/ProxyPool/proxypool/tester.py", line 35, in test_single_proxy
    async with session.get(TEST_URL, proxy=real_proxy, timeout=5, allow_redirects=False) as response:
  File "/home/python/.virtualenvs/Env1/lib/python3.5/site-packages/aiohttp/client.py", line 690, in __aenter__
    self._resp = yield from self._coro
  File "/home/python/.virtualenvs/Env1/lib/python3.5/site-packages/aiohttp/client.py", line 267, in _request
    conn = yield from self._connector.connect(req)
  File "/home/python/.virtualenvs/Env1/lib/python3.5/site-packages/aiohttp/connector.py", line 402, in connect
    proto = yield from self._create_connection(req)
  File "/home/python/.virtualenvs/Env1/lib/python3.5/site-packages/aiohttp/connector.py", line 747, in _create_connection
    _, proto = yield from self._create_proxy_connection(req)
  File "/home/python/.virtualenvs/Env1/lib/python3.5/site-packages/aiohttp/connector.py", line 880, in _create_proxy_connection
    proxy_req, client_error=ClientProxyConnectionError)
  File "/home/python/.virtualenvs/Env1/lib/python3.5/site-packages/aiohttp/connector.py", line 860, in _create_direct_connection
    raise last_exc
  File "/home/python/.virtualenvs/Env1/lib/python3.5/site-packages/aiohttp/connector.py", line 832, in _create_direct_connection
    req=req, client_error=client_error)
  File "/home/python/.virtualenvs/Env1/lib/python3.5/site-packages/aiohttp/connector.py", line 804, in _wrap_create_connection
    raise client_error(req.connection_key, exc) from exc
aiohttp.client_exceptions.ClientProxyConnectionError: Cannot connect to host 218.95.81.250:9000 ssl:False [Connect call failed ('218.95.81.250', 9000)]

During handling of the above exception, another exception occurred:

Traceback (most recent call last):
  File "/usr/lib/python3.5/asyncio/tasks.py", line 241, in _step
    result = coro.throw(exc)
  File "/home/python/Desktop/spider3/ProxyPool/proxypool/tester.py", line 44, in test_single_proxy
    self.redis.decrease(proxy)
  File "/home/python/Desktop/spider3/ProxyPool/proxypool/db.py", line 77, in decrease
    logger.info('代理%s, 当前分数%d移除' % (proxy, score))
TypeError: %d format: a number is required, not NoneType
2018-09-21 18:53:09,759 - asyncio - ERROR - Task exception was never retrieved
future: <Task finished coro=<Tester.test_single_proxy() done, defined at /home/python/Desktop/spider3/ProxyPool/proxypool/tester.py:20> exception=TypeError('%d format: a number is required, not NoneType',)>
Traceback (most recent call last):
  File "/home/python/Desktop/spider3/ProxyPool/proxypool/tester.py", line 35, in test_single_proxy
    async with session.get(TEST_URL, proxy=real_proxy, timeout=5, allow_redirects=False) as response:
  File "/home/python/.virtualenvs/Env1/lib/python3.5/site-packages/aiohttp/client.py", line 690, in __aenter__
    self._resp = yield from self._coro
  File "/home/python/.virtualenvs/Env1/lib/python3.5/site-packages/aiohttp/client.py", line 341, in _request
    break
  File "/home/python/.virtualenvs/Env1/lib/python3.5/site-packages/aiohttp/helpers.py", line 732, in __exit__
    raise asyncio.TimeoutError from None
concurrent.futures._base.TimeoutError

During handling of the above exception, another exception occurred:

Traceback (most recent call last):
  File "/usr/lib/python3.5/asyncio/tasks.py", line 241, in _step
    result = coro.throw(exc)
  File "/home/python/Desktop/spider3/ProxyPool/proxypool/tester.py", line 44, in test_single_proxy
    self.redis.decrease(proxy)
  File "/home/python/Desktop/spider3/ProxyPool/proxypool/db.py", line 77, in decrease
    logger.info('代理%s, 当前分数%d移除' % (proxy, score))
TypeError: %d format: a number is required, not NoneType
2018-09-21 18:53:09,759 - asyncio - ERROR - Task exception was never retrieved
future: <Task finished coro=<Tester.test_single_proxy() done, defined at /home/python/Desktop/spider3/ProxyPool/proxypool/tester.py:20> exception=TypeError('%d format: a number is required, not NoneType',)>
Traceback (most recent call last):
  File "/home/python/Desktop/spider3/ProxyPool/proxypool/tester.py", line 35, in test_single_proxy
    async with session.get(TEST_URL, proxy=real_proxy, timeout=5, allow_redirects=False) as response:
  File "/home/python/.virtualenvs/Env1/lib/python3.5/site-packages/aiohttp/client.py", line 690, in __aenter__
    self._resp = yield from self._coro
  File "/home/python/.virtualenvs/Env1/lib/python3.5/site-packages/aiohttp/client.py", line 341, in _request
    break
  File "/home/python/.virtualenvs/Env1/lib/python3.5/site-packages/aiohttp/helpers.py", line 732, in __exit__
    raise asyncio.TimeoutError from None
concurrent.futures._base.TimeoutError

During handling of the above exception, another exception occurred:

Traceback (most recent call last):
  File "/usr/lib/python3.5/asyncio/tasks.py", line 241, in _step
    result = coro.throw(exc)
  File "/home/python/Desktop/spider3/ProxyPool/proxypool/tester.py", line 44, in test_single_proxy
    self.redis.decrease(proxy)
  File "/home/python/Desktop/spider3/ProxyPool/proxypool/db.py", line 77, in decrease
    logger.info('代理%s, 当前分数%d移除' % (proxy, score))
TypeError: %d format: a number is required, not NoneType
2018-09-21 18:53:09,760 - asyncio - ERROR - Task exception was never retrieved
future: <Task finished coro=<Tester.test_single_proxy() done, defined at /home/python/Desktop/spider3/ProxyPool/proxypool/tester.py:20> exception=TypeError('%d format: a number is required, not NoneType',)>
Traceback (most recent call last):
  File "/home/python/Desktop/spider3/ProxyPool/proxypool/tester.py", line 35, in test_single_proxy
    async with session.get(TEST_URL, proxy=real_proxy, timeout=5, allow_redirects=False) as response:
  File "/home/python/.virtualenvs/Env1/lib/python3.5/site-packages/aiohttp/client.py", line 690, in __aenter__
    self._resp = yield from self._coro
  File "/home/python/.virtualenvs/Env1/lib/python3.5/site-packages/aiohttp/client.py", line 341, in _request
    break
  File "/home/python/.virtualenvs/Env1/lib/python3.5/site-packages/aiohttp/helpers.py", line 732, in __exit__
    raise asyncio.TimeoutError from None
concurrent.futures._base.TimeoutError

During handling of the above exception, another exception occurred:

Traceback (most recent call last):
  File "/usr/lib/python3.5/asyncio/tasks.py", line 241, in _step
    result = coro.throw(exc)
  File "/home/python/Desktop/spider3/ProxyPool/proxypool/tester.py", line 44, in test_single_proxy
    self.redis.decrease(proxy)
  File "/home/python/Desktop/spider3/ProxyPool/proxypool/db.py", line 77, in decrease
    logger.info('代理%s, 当前分数%d移除' % (proxy, score))
TypeError: %d format: a number is required, not NoneType
2018-09-21 18:53:09,760 - asyncio - ERROR - Task exception was never retrieved
future: <Task finished coro=<Tester.test_single_proxy() done, defined at /home/python/Desktop/spider3/ProxyPool/proxypool/tester.py:20> exception=TypeError('%d format: a number is required, not NoneType',)>
Traceback (most recent call last):
  File "/home/python/Desktop/spider3/ProxyPool/proxypool/tester.py", line 35, in test_single_proxy
    async with session.get(TEST_URL, proxy=real_proxy, timeout=5, allow_redirects=False) as response:
  File "/home/python/.virtualenvs/Env1/lib/python3.5/site-packages/aiohttp/client.py", line 690, in __aenter__
    self._resp = yield from self._coro
  File "/home/python/.virtualenvs/Env1/lib/python3.5/site-packages/aiohttp/client.py", line 341, in _request
    break
  File "/home/python/.virtualenvs/Env1/lib/python3.5/site-packages/aiohttp/helpers.py", line 732, in __exit__
    raise asyncio.TimeoutError from None
concurrent.futures._base.TimeoutError

During handling of the above exception, another exception occurred:

Traceback (most recent call last):
  File "/usr/lib/python3.5/asyncio/tasks.py", line 241, in _step
    result = coro.throw(exc)
  File "/home/python/Desktop/spider3/ProxyPool/proxypool/tester.py", line 44, in test_single_proxy
    self.redis.decrease(proxy)
  File "/home/python/Desktop/spider3/ProxyPool/proxypool/db.py", line 77, in decrease
    logger.info('代理%s, 当前分数%d移除' % (proxy, score))
TypeError: %d format: a number is required, not NoneType
2018-09-21 18:53:09,761 - asyncio - ERROR - Task exception was never retrieved
future: <Task finished coro=<Tester.test_single_proxy() done, defined at /home/python/Desktop/spider3/ProxyPool/proxypool/tester.py:20> exception=TypeError('%d format: a number is required, not NoneType',)>
Traceback (most recent call last):
  File "/home/python/Desktop/spider3/ProxyPool/proxypool/tester.py", line 35, in test_single_proxy
    async with session.get(TEST_URL, proxy=real_proxy, timeout=5, allow_redirects=False) as response:
  File "/home/python/.virtualenvs/Env1/lib/python3.5/site-packages/aiohttp/client.py", line 690, in __aenter__
    self._resp = yield from self._coro
  File "/home/python/.virtualenvs/Env1/lib/python3.5/site-packages/aiohttp/client.py", line 341, in _request
    break
  File "/home/python/.virtualenvs/Env1/lib/python3.5/site-packages/aiohttp/helpers.py", line 732, in __exit__
    raise asyncio.TimeoutError from None
concurrent.futures._base.TimeoutError

During handling of the above exception, another exception occurred:

Traceback (most recent call last):
  File "/usr/lib/python3.5/asyncio/tasks.py", line 241, in _step
    result = coro.throw(exc)
  File "/home/python/Desktop/spider3/ProxyPool/proxypool/tester.py", line 44, in test_single_proxy
    self.redis.decrease(proxy)
  File "/home/python/Desktop/spider3/ProxyPool/proxypool/db.py", line 77, in decrease
    logger.info('代理%s, 当前分数%d移除' % (proxy, score))
TypeError: %d format: a number is required, not NoneType
2018-09-21 18:53:09,761 - asyncio - ERROR - Task exception was never retrieved
future: <Task finished coro=<Tester.test_single_proxy() done, defined at /home/python/Desktop/spider3/ProxyPool/proxypool/tester.py:20> exception=TypeError('%d format: a number is required, not NoneType',)>
Traceback (most recent call last):
  File "/home/python/.virtualenvs/Env1/lib/python3.5/site-packages/aiohttp/client_reqrep.py", line 624, in start
    (message, payload) = yield from self._protocol.read()
  File "/home/python/.virtualenvs/Env1/lib/python3.5/site-packages/aiohttp/streams.py", line 554, in read
    yield from self._waiter
  File "/usr/lib/python3.5/asyncio/futures.py", line 361, in __iter__
    yield self  # This tells Task to wait for completion.
  File "/usr/lib/python3.5/asyncio/tasks.py", line 296, in _wakeup
    future.result()
  File "/usr/lib/python3.5/asyncio/futures.py", line 274, in result
    raise self._exception
  File "/home/python/.virtualenvs/Env1/lib/python3.5/site-packages/aiohttp/client_proto.py", line 167, in data_received
    messages, upgraded, tail = self._parser.feed_data(data)
  File "aiohttp/_http_parser.pyx", line 295, in aiohttp._http_parser.HttpParser.feed_data
aiohttp.http_exceptions.BadHttpMessage: 400, message='invalid constant string'

The above exception was the direct cause of the following exception:

Traceback (most recent call last):
  File "/home/python/Desktop/spider3/ProxyPool/proxypool/tester.py", line 35, in test_single_proxy
    async with session.get(TEST_URL, proxy=real_proxy, timeout=5, allow_redirects=False) as response:
  File "/home/python/.virtualenvs/Env1/lib/python3.5/site-packages/aiohttp/client.py", line 690, in __aenter__
    self._resp = yield from self._coro
  File "/home/python/.virtualenvs/Env1/lib/python3.5/site-packages/aiohttp/client.py", line 267, in _request
    conn = yield from self._connector.connect(req)
  File "/home/python/.virtualenvs/Env1/lib/python3.5/site-packages/aiohttp/connector.py", line 402, in connect
    proto = yield from self._create_connection(req)
  File "/home/python/.virtualenvs/Env1/lib/python3.5/site-packages/aiohttp/connector.py", line 747, in _create_connection
    _, proto = yield from self._create_proxy_connection(req)
  File "/home/python/.virtualenvs/Env1/lib/python3.5/site-packages/aiohttp/connector.py", line 906, in _create_proxy_connection
    resp = yield from proxy_resp.start(conn, True)
  File "/home/python/.virtualenvs/Env1/lib/python3.5/site-packages/aiohttp/client_reqrep.py", line 629, in start
    message=exc.message, headers=exc.headers) from exc
aiohttp.client_exceptions.ClientResponseError: 400, message='invalid constant string'

During handling of the above exception, another exception occurred:

Traceback (most recent call last):
  File "/usr/lib/python3.5/asyncio/tasks.py", line 241, in _step
    result = coro.throw(exc)
  File "/home/python/Desktop/spider3/ProxyPool/proxypool/tester.py", line 44, in test_single_proxy
    self.redis.decrease(proxy)
  File "/home/python/Desktop/spider3/ProxyPool/proxypool/db.py", line 77, in decrease
    logger.info('代理%s, 当前分数%d移除' % (proxy, score))
TypeError: %d format: a number is required, not NoneType
2018-09-21 18:53:09,764 - asyncio - ERROR - Task exception was never retrieved
future: <Task finished coro=<Tester.test_single_proxy() done, defined at /home/python/Desktop/spider3/ProxyPool/proxypool/tester.py:20> exception=TypeError('%d format: a number is required, not NoneType',)>
Traceback (most recent call last):
  File "/home/python/Desktop/spider3/ProxyPool/proxypool/tester.py", line 35, in test_single_proxy
    async with session.get(TEST_URL, proxy=real_proxy, timeout=5, allow_redirects=False) as response:
  File "/home/python/.virtualenvs/Env1/lib/python3.5/site-packages/aiohttp/client.py", line 690, in __aenter__
    self._resp = yield from self._coro
  File "/home/python/.virtualenvs/Env1/lib/python3.5/site-packages/aiohttp/client.py", line 341, in _request
    break
  File "/home/python/.virtualenvs/Env1/lib/python3.5/site-packages/aiohttp/helpers.py", line 732, in __exit__
    raise asyncio.TimeoutError from None
concurrent.futures._base.TimeoutError

During handling of the above exception, another exception occurred:

Traceback (most recent call last):
  File "/usr/lib/python3.5/asyncio/tasks.py", line 241, in _step
    result = coro.throw(exc)
  File "/home/python/Desktop/spider3/ProxyPool/proxypool/tester.py", line 44, in test_single_proxy
    self.redis.decrease(proxy)
  File "/home/python/Desktop/spider3/ProxyPool/proxypool/db.py", line 77, in decrease
    logger.info('代理%s, 当前分数%d移除' % (proxy, score))
TypeError: %d format: a number is required, not NoneType
2018-09-21 18:53:09,764 - asyncio - ERROR - Task exception was never retrieved
future: <Task finished coro=<Tester.test_single_proxy() done, defined at /home/python/Desktop/spider3/ProxyPool/proxypool/tester.py:20> exception=TypeError('%d format: a number is required, not NoneType',)>
Traceback (most recent call last):
  File "/home/python/Desktop/spider3/ProxyPool/proxypool/tester.py", line 35, in test_single_proxy
    async with session.get(TEST_URL, proxy=real_proxy, timeout=5, allow_redirects=False) as response:
  File "/home/python/.virtualenvs/Env1/lib/python3.5/site-packages/aiohttp/client.py", line 690, in __aenter__
    self._resp = yield from self._coro
  File "/home/python/.virtualenvs/Env1/lib/python3.5/site-packages/aiohttp/client.py", line 341, in _request
    break
  File "/home/python/.virtualenvs/Env1/lib/python3.5/site-packages/aiohttp/helpers.py", line 732, in __exit__
    raise asyncio.TimeoutError from None
concurrent.futures._base.TimeoutError

During handling of the above exception, another exception occurred:

Traceback (most recent call last):
  File "/usr/lib/python3.5/asyncio/tasks.py", line 241, in _step
    result = coro.throw(exc)
  File "/home/python/Desktop/spider3/ProxyPool/proxypool/tester.py", line 44, in test_single_proxy
    self.redis.decrease(proxy)
  File "/home/python/Desktop/spider3/ProxyPool/proxypool/db.py", line 77, in decrease
    logger.info('代理%s, 当前分数%d移除' % (proxy, score))
TypeError: %d format: a number is required, not NoneType
2018-09-21 18:53:09,765 - asyncio - ERROR - Task exception was never retrieved
future: <Task finished coro=<Tester.test_single_proxy() done, defined at /home/python/Desktop/spider3/ProxyPool/proxypool/tester.py:20> exception=TypeError('%d format: a number is required, not NoneType',)>
Traceback (most recent call last):
  File "/home/python/Desktop/spider3/ProxyPool/proxypool/tester.py", line 35, in test_single_proxy
    async with session.get(TEST_URL, proxy=real_proxy, timeout=5, allow_redirects=False) as response:
  File "/home/python/.virtualenvs/Env1/lib/python3.5/site-packages/aiohttp/client.py", line 690, in __aenter__
    self._resp = yield from self._coro
  File "/home/python/.virtualenvs/Env1/lib/python3.5/site-packages/aiohttp/client.py", line 341, in _request
    break
  File "/home/python/.virtualenvs/Env1/lib/python3.5/site-packages/aiohttp/helpers.py", line 732, in __exit__
    raise asyncio.TimeoutError from None
concurrent.futures._base.TimeoutError

During handling of the above exception, another exception occurred:

Traceback (most recent call last):
  File "/usr/lib/python3.5/asyncio/tasks.py", line 241, in _step
    result = coro.throw(exc)
  File "/home/python/Desktop/spider3/ProxyPool/proxypool/tester.py", line 44, in test_single_proxy
    self.redis.decrease(proxy)
  File "/home/python/Desktop/spider3/ProxyPool/proxypool/db.py", line 77, in decrease
    logger.info('代理%s, 当前分数%d移除' % (proxy, score))
TypeError: %d format: a number is required, not NoneType
2018-09-21 18:53:09,765 - asyncio - ERROR - Task exception was never retrieved
future: <Task finished coro=<Tester.test_single_proxy() done, defined at /home/python/Desktop/spider3/ProxyPool/proxypool/tester.py:20> exception=TypeError('%d format: a number is required, not NoneType',)>
Traceback (most recent call last):
  File "/home/python/Desktop/spider3/ProxyPool/proxypool/tester.py", line 35, in test_single_proxy
    async with session.get(TEST_URL, proxy=real_proxy, timeout=5, allow_redirects=False) as response:
  File "/home/python/.virtualenvs/Env1/lib/python3.5/site-packages/aiohttp/client.py", line 690, in __aenter__
    self._resp = yield from self._coro
  File "/home/python/.virtualenvs/Env1/lib/python3.5/site-packages/aiohttp/client.py", line 341, in _request
    break
  File "/home/python/.virtualenvs/Env1/lib/python3.5/site-packages/aiohttp/helpers.py", line 732, in __exit__
    raise asyncio.TimeoutError from None
concurrent.futures._base.TimeoutError

During handling of the above exception, another exception occurred:

Traceback (most recent call last):
  File "/usr/lib/python3.5/asyncio/tasks.py", line 241, in _step
    result = coro.throw(exc)
  File "/home/python/Desktop/spider3/ProxyPool/proxypool/tester.py", line 44, in test_single_proxy
    self.redis.decrease(proxy)
  File "/home/python/Desktop/spider3/ProxyPool/proxypool/db.py", line 77, in decrease
    logger.info('代理%s, 当前分数%d移除' % (proxy, score))
TypeError: %d format: a number is required, not NoneType
2018-09-21 18:53:09,765 - asyncio - ERROR - Task exception was never retrieved
future: <Task finished coro=<Tester.test_single_proxy() done, defined at /home/python/Desktop/spider3/ProxyPool/proxypool/tester.py:20> exception=TypeError('%d format: a number is required, not NoneType',)>
Traceback (most recent call last):
  File "/home/python/Desktop/spider3/ProxyPool/proxypool/tester.py", line 35, in test_single_proxy
    async with session.get(TEST_URL, proxy=real_proxy, timeout=5, allow_redirects=False) as response:
  File "/home/python/.virtualenvs/Env1/lib/python3.5/site-packages/aiohttp/client.py", line 690, in __aenter__
    self._resp = yield from self._coro
  File "/home/python/.virtualenvs/Env1/lib/python3.5/site-packages/aiohttp/client.py", line 341, in _request
    break
  File "/home/python/.virtualenvs/Env1/lib/python3.5/site-packages/aiohttp/helpers.py", line 732, in __exit__
    raise asyncio.TimeoutError from None
concurrent.futures._base.TimeoutError

During handling of the above exception, another exception occurred:

Traceback (most recent call last):
  File "/usr/lib/python3.5/asyncio/tasks.py", line 241, in _step
    result = coro.throw(exc)
  File "/home/python/Desktop/spider3/ProxyPool/proxypool/tester.py", line 44, in test_single_proxy
    self.redis.decrease(proxy)
  File "/home/python/Desktop/spider3/ProxyPool/proxypool/db.py", line 77, in decrease
    logger.info('代理%s, 当前分数%d移除' % (proxy, score))
TypeError: %d format: a number is required, not NoneType
2018-09-21 18:53:29,742 - asyncio - ERROR - Task exception was never retrieved
future: <Task finished coro=<Tester.test_single_proxy() done, defined at /home/python/Desktop/spider3/ProxyPool/proxypool/tester.py:20> exception=TypeError('%d format: a number is required, not NoneType',)>
Traceback (most recent call last):
  File "/home/python/Desktop/spider3/ProxyPool/proxypool/tester.py", line 35, in test_single_proxy
    async with session.get(TEST_URL, proxy=real_proxy, timeout=5, allow_redirects=False) as response:
  File "/home/python/.virtualenvs/Env1/lib/python3.5/site-packages/aiohttp/client.py", line 690, in __aenter__
    self._resp = yield from self._coro
  File "/home/python/.virtualenvs/Env1/lib/python3.5/site-packages/aiohttp/client.py", line 341, in _request
    break
  File "/home/python/.virtualenvs/Env1/lib/python3.5/site-packages/aiohttp/helpers.py", line 732, in __exit__
    raise asyncio.TimeoutError from None
concurrent.futures._base.TimeoutError

During handling of the above exception, another exception occurred:

Traceback (most recent call last):
  File "/usr/lib/python3.5/asyncio/tasks.py", line 241, in _step
    result = coro.throw(exc)
  File "/home/python/Desktop/spider3/ProxyPool/proxypool/tester.py", line 44, in test_single_proxy
    self.redis.decrease(proxy)
  File "/home/python/Desktop/spider3/ProxyPool/proxypool/db.py", line 77, in decrease
    logger.info('代理%s, 当前分数%d移除' % (proxy, score))
TypeError: %d format: a number is required, not NoneType
2018-09-21 18:53:29,744 - asyncio - ERROR - Task exception was never retrieved
future: <Task finished coro=<Tester.test_single_proxy() done, defined at /home/python/Desktop/spider3/ProxyPool/proxypool/tester.py:20> exception=TypeError('%d format: a number is required, not NoneType',)>
Traceback (most recent call last):
  File "/home/python/Desktop/spider3/ProxyPool/proxypool/tester.py", line 35, in test_single_proxy
    async with session.get(TEST_URL, proxy=real_proxy, timeout=5, allow_redirects=False) as response:
  File "/home/python/.virtualenvs/Env1/lib/python3.5/site-packages/aiohttp/client.py", line 690, in __aenter__
    self._resp = yield from self._coro
  File "/home/python/.virtualenvs/Env1/lib/python3.5/site-packages/aiohttp/client.py", line 341, in _request
    break
  File "/home/python/.virtualenvs/Env1/lib/python3.5/site-packages/aiohttp/helpers.py", line 732, in __exit__
    raise asyncio.TimeoutError from None
concurrent.futures._base.TimeoutError

During handling of the above exception, another exception occurred:

Traceback (most recent call last):
  File "/usr/lib/python3.5/asyncio/tasks.py", line 241, in _step
    result = coro.throw(exc)
  File "/home/python/Desktop/spider3/ProxyPool/proxypool/tester.py", line 44, in test_single_proxy
    self.redis.decrease(proxy)
  File "/home/python/Desktop/spider3/ProxyPool/proxypool/db.py", line 77, in decrease
    logger.info('代理%s, 当前分数%d移除' % (proxy, score))
TypeError: %d format: a number is required, not NoneType
2018-09-21 18:54:02,706 - tester - ERROR - 测试器发生错误Set of coroutines/Futures is empty.
Traceback (most recent call last):
  File "/home/python/Desktop/spider3/ProxyPool/proxypool/tester.py", line 66, in run
    loop.run_until_complete(asyncio.wait(tasks))
  File "/usr/lib/python3.5/asyncio/base_events.py", line 387, in run_until_complete
    return future.result()
  File "/usr/lib/python3.5/asyncio/futures.py", line 274, in result
    raise self._exception
  File "/usr/lib/python3.5/asyncio/tasks.py", line 239, in _step
    result = coro.send(None)
  File "/usr/lib/python3.5/asyncio/tasks.py", line 338, in wait
    raise ValueError('Set of coroutines/Futures is empty.')
ValueError: Set of coroutines/Futures is empty.
2018-09-21 18:54:04,707 - tester - ERROR - 测试器发生错误Set of coroutines/Futures is empty.
Traceback (most recent call last):
  File "/home/python/Desktop/spider3/ProxyPool/proxypool/tester.py", line 66, in run
    loop.run_until_complete(asyncio.wait(tasks))
  File "/usr/lib/python3.5/asyncio/base_events.py", line 387, in run_until_complete
    return future.result()
  File "/usr/lib/python3.5/asyncio/futures.py", line 274, in result
    raise self._exception
  File "/usr/lib/python3.5/asyncio/tasks.py", line 239, in _step
    result = coro.send(None)
  File "/usr/lib/python3.5/asyncio/tasks.py", line 338, in wait
    raise ValueError('Set of coroutines/Futures is empty.')
ValueError: Set of coroutines/Futures is empty.
2018-09-21 18:55:44,843 - asyncio - ERROR - Task exception was never retrieved
future: <Task finished coro=<Tester.test_single_proxy() done, defined at /home/python/Desktop/spider3/ProxyPool/proxypool/tester.py:20> exception=TypeError('%d format: a number is required, not NoneType',)>
Traceback (most recent call last):
  File "/home/python/Desktop/spider3/ProxyPool/proxypool/tester.py", line 35, in test_single_proxy
    async with session.get(TEST_URL, proxy=real_proxy, timeout=5, allow_redirects=False) as response:
  File "/home/python/.virtualenvs/Env1/lib/python3.5/site-packages/aiohttp/client.py", line 690, in __aenter__
    self._resp = yield from self._coro
  File "/home/python/.virtualenvs/Env1/lib/python3.5/site-packages/aiohttp/client.py", line 341, in _request
    break
  File "/home/python/.virtualenvs/Env1/lib/python3.5/site-packages/aiohttp/helpers.py", line 732, in __exit__
    raise asyncio.TimeoutError from None
concurrent.futures._base.TimeoutError

During handling of the above exception, another exception occurred:

Traceback (most recent call last):
  File "/usr/lib/python3.5/asyncio/tasks.py", line 241, in _step
    result = coro.throw(exc)
  File "/home/python/Desktop/spider3/ProxyPool/proxypool/tester.py", line 44, in test_single_proxy
    self.redis.decrease(proxy)
  File "/home/python/Desktop/spider3/ProxyPool/proxypool/db.py", line 77, in decrease
    logger.info('代理%s, 当前分数%d移除' % (proxy, score))
TypeError: %d format: a number is required, not NoneType
2018-09-21 18:55:44,844 - asyncio - ERROR - Task exception was never retrieved
future: <Task finished coro=<Tester.test_single_proxy() done, defined at /home/python/Desktop/spider3/ProxyPool/proxypool/tester.py:20> exception=TypeError('%d format: a number is required, not NoneType',)>
Traceback (most recent call last):
  File "/home/python/Desktop/spider3/ProxyPool/proxypool/tester.py", line 35, in test_single_proxy
    async with session.get(TEST_URL, proxy=real_proxy, timeout=5, allow_redirects=False) as response:
  File "/home/python/.virtualenvs/Env1/lib/python3.5/site-packages/aiohttp/client.py", line 690, in __aenter__
    self._resp = yield from self._coro
  File "/home/python/.virtualenvs/Env1/lib/python3.5/site-packages/aiohttp/client.py", line 341, in _request
    break
  File "/home/python/.virtualenvs/Env1/lib/python3.5/site-packages/aiohttp/helpers.py", line 732, in __exit__
    raise asyncio.TimeoutError from None
concurrent.futures._base.TimeoutError

During handling of the above exception, another exception occurred:

Traceback (most recent call last):
  File "/usr/lib/python3.5/asyncio/tasks.py", line 241, in _step
    result = coro.throw(exc)
  File "/home/python/Desktop/spider3/ProxyPool/proxypool/tester.py", line 44, in test_single_proxy
    self.redis.decrease(proxy)
  File "/home/python/Desktop/spider3/ProxyPool/proxypool/db.py", line 77, in decrease
    logger.info('代理%s, 当前分数%d移除' % (proxy, score))
TypeError: %d format: a number is required, not NoneType
2018-09-21 18:55:44,844 - asyncio - ERROR - Task exception was never retrieved
future: <Task finished coro=<Tester.test_single_proxy() done, defined at /home/python/Desktop/spider3/ProxyPool/proxypool/tester.py:20> exception=TypeError('%d format: a number is required, not NoneType',)>
Traceback (most recent call last):
  File "/home/python/Desktop/spider3/ProxyPool/proxypool/tester.py", line 35, in test_single_proxy
    async with session.get(TEST_URL, proxy=real_proxy, timeout=5, allow_redirects=False) as response:
  File "/home/python/.virtualenvs/Env1/lib/python3.5/site-packages/aiohttp/client.py", line 690, in __aenter__
    self._resp = yield from self._coro
  File "/home/python/.virtualenvs/Env1/lib/python3.5/site-packages/aiohttp/client.py", line 341, in _request
    break
  File "/home/python/.virtualenvs/Env1/lib/python3.5/site-packages/aiohttp/helpers.py", line 732, in __exit__
    raise asyncio.TimeoutError from None
concurrent.futures._base.TimeoutError

During handling of the above exception, another exception occurred:

Traceback (most recent call last):
  File "/usr/lib/python3.5/asyncio/tasks.py", line 241, in _step
    result = coro.throw(exc)
  File "/home/python/Desktop/spider3/ProxyPool/proxypool/tester.py", line 44, in test_single_proxy
    self.redis.decrease(proxy)
  File "/home/python/Desktop/spider3/ProxyPool/proxypool/db.py", line 77, in decrease
    logger.info('代理%s, 当前分数%d移除' % (proxy, score))
TypeError: %d format: a number is required, not NoneType
2018-09-21 18:55:44,845 - asyncio - ERROR - Task exception was never retrieved
future: <Task finished coro=<Tester.test_single_proxy() done, defined at /home/python/Desktop/spider3/ProxyPool/proxypool/tester.py:20> exception=TypeError('%d format: a number is required, not NoneType',)>
Traceback (most recent call last):
  File "/home/python/Desktop/spider3/ProxyPool/proxypool/tester.py", line 35, in test_single_proxy
    async with session.get(TEST_URL, proxy=real_proxy, timeout=5, allow_redirects=False) as response:
  File "/home/python/.virtualenvs/Env1/lib/python3.5/site-packages/aiohttp/client.py", line 690, in __aenter__
    self._resp = yield from self._coro
  File "/home/python/.virtualenvs/Env1/lib/python3.5/site-packages/aiohttp/client.py", line 341, in _request
    break
  File "/home/python/.virtualenvs/Env1/lib/python3.5/site-packages/aiohttp/helpers.py", line 732, in __exit__
    raise asyncio.TimeoutError from None
concurrent.futures._base.TimeoutError

During handling of the above exception, another exception occurred:

Traceback (most recent call last):
  File "/usr/lib/python3.5/asyncio/tasks.py", line 241, in _step
    result = coro.throw(exc)
  File "/home/python/Desktop/spider3/ProxyPool/proxypool/tester.py", line 44, in test_single_proxy
    self.redis.decrease(proxy)
  File "/home/python/Desktop/spider3/ProxyPool/proxypool/db.py", line 77, in decrease
    logger.info('代理%s, 当前分数%d移除' % (proxy, score))
TypeError: %d format: a number is required, not NoneType
2018-09-21 18:55:44,845 - asyncio - ERROR - Task exception was never retrieved
future: <Task finished coro=<Tester.test_single_proxy() done, defined at /home/python/Desktop/spider3/ProxyPool/proxypool/tester.py:20> exception=TypeError('%d format: a number is required, not NoneType',)>
Traceback (most recent call last):
  File "/home/python/Desktop/spider3/ProxyPool/proxypool/tester.py", line 35, in test_single_proxy
    async with session.get(TEST_URL, proxy=real_proxy, timeout=5, allow_redirects=False) as response:
  File "/home/python/.virtualenvs/Env1/lib/python3.5/site-packages/aiohttp/client.py", line 690, in __aenter__
    self._resp = yield from self._coro
  File "/home/python/.virtualenvs/Env1/lib/python3.5/site-packages/aiohttp/client.py", line 341, in _request
    break
  File "/home/python/.virtualenvs/Env1/lib/python3.5/site-packages/aiohttp/helpers.py", line 732, in __exit__
    raise asyncio.TimeoutError from None
concurrent.futures._base.TimeoutError

During handling of the above exception, another exception occurred:

Traceback (most recent call last):
  File "/usr/lib/python3.5/asyncio/tasks.py", line 241, in _step
    result = coro.throw(exc)
  File "/home/python/Desktop/spider3/ProxyPool/proxypool/tester.py", line 44, in test_single_proxy
    self.redis.decrease(proxy)
  File "/home/python/Desktop/spider3/ProxyPool/proxypool/db.py", line 77, in decrease
    logger.info('代理%s, 当前分数%d移除' % (proxy, score))
TypeError: %d format: a number is required, not NoneType
2018-09-21 18:55:44,846 - asyncio - ERROR - Task exception was never retrieved
future: <Task finished coro=<Tester.test_single_proxy() done, defined at /home/python/Desktop/spider3/ProxyPool/proxypool/tester.py:20> exception=TypeError('%d format: a number is required, not NoneType',)>
Traceback (most recent call last):
  File "/home/python/Desktop/spider3/ProxyPool/proxypool/tester.py", line 35, in test_single_proxy
    async with session.get(TEST_URL, proxy=real_proxy, timeout=5, allow_redirects=False) as response:
  File "/home/python/.virtualenvs/Env1/lib/python3.5/site-packages/aiohttp/client.py", line 690, in __aenter__
    self._resp = yield from self._coro
  File "/home/python/.virtualenvs/Env1/lib/python3.5/site-packages/aiohttp/client.py", line 341, in _request
    break
  File "/home/python/.virtualenvs/Env1/lib/python3.5/site-packages/aiohttp/helpers.py", line 732, in __exit__
    raise asyncio.TimeoutError from None
concurrent.futures._base.TimeoutError

During handling of the above exception, another exception occurred:

Traceback (most recent call last):
  File "/usr/lib/python3.5/asyncio/tasks.py", line 241, in _step
    result = coro.throw(exc)
  File "/home/python/Desktop/spider3/ProxyPool/proxypool/tester.py", line 44, in test_single_proxy
    self.redis.decrease(proxy)
  File "/home/python/Desktop/spider3/ProxyPool/proxypool/db.py", line 77, in decrease
    logger.info('代理%s, 当前分数%d移除' % (proxy, score))
TypeError: %d format: a number is required, not NoneType
2018-09-21 18:55:44,847 - asyncio - ERROR - Task exception was never retrieved
future: <Task finished coro=<Tester.test_single_proxy() done, defined at /home/python/Desktop/spider3/ProxyPool/proxypool/tester.py:20> exception=TypeError('%d format: a number is required, not NoneType',)>
Traceback (most recent call last):
  File "/home/python/Desktop/spider3/ProxyPool/proxypool/tester.py", line 35, in test_single_proxy
    async with session.get(TEST_URL, proxy=real_proxy, timeout=5, allow_redirects=False) as response:
  File "/home/python/.virtualenvs/Env1/lib/python3.5/site-packages/aiohttp/client.py", line 690, in __aenter__
    self._resp = yield from self._coro
  File "/home/python/.virtualenvs/Env1/lib/python3.5/site-packages/aiohttp/client.py", line 341, in _request
    break
  File "/home/python/.virtualenvs/Env1/lib/python3.5/site-packages/aiohttp/helpers.py", line 732, in __exit__
    raise asyncio.TimeoutError from None
concurrent.futures._base.TimeoutError

During handling of the above exception, another exception occurred:

Traceback (most recent call last):
  File "/usr/lib/python3.5/asyncio/tasks.py", line 241, in _step
    result = coro.throw(exc)
  File "/home/python/Desktop/spider3/ProxyPool/proxypool/tester.py", line 44, in test_single_proxy
    self.redis.decrease(proxy)
  File "/home/python/Desktop/spider3/ProxyPool/proxypool/db.py", line 77, in decrease
    logger.info('代理%s, 当前分数%d移除' % (proxy, score))
TypeError: %d format: a number is required, not NoneType
2018-09-21 18:55:44,847 - asyncio - ERROR - Task exception was never retrieved
future: <Task finished coro=<Tester.test_single_proxy() done, defined at /home/python/Desktop/spider3/ProxyPool/proxypool/tester.py:20> exception=TypeError('%d format: a number is required, not NoneType',)>
Traceback (most recent call last):
  File "/home/python/Desktop/spider3/ProxyPool/proxypool/tester.py", line 35, in test_single_proxy
    async with session.get(TEST_URL, proxy=real_proxy, timeout=5, allow_redirects=False) as response:
  File "/home/python/.virtualenvs/Env1/lib/python3.5/site-packages/aiohttp/client.py", line 690, in __aenter__
    self._resp = yield from self._coro
  File "/home/python/.virtualenvs/Env1/lib/python3.5/site-packages/aiohttp/client.py", line 341, in _request
    break
  File "/home/python/.virtualenvs/Env1/lib/python3.5/site-packages/aiohttp/helpers.py", line 732, in __exit__
    raise asyncio.TimeoutError from None
concurrent.futures._base.TimeoutError

During handling of the above exception, another exception occurred:

Traceback (most recent call last):
  File "/usr/lib/python3.5/asyncio/tasks.py", line 241, in _step
    result = coro.throw(exc)
  File "/home/python/Desktop/spider3/ProxyPool/proxypool/tester.py", line 44, in test_single_proxy
    self.redis.decrease(proxy)
  File "/home/python/Desktop/spider3/ProxyPool/proxypool/db.py", line 77, in decrease
    logger.info('代理%s, 当前分数%d移除' % (proxy, score))
TypeError: %d format: a number is required, not NoneType
2018-09-21 18:55:44,848 - asyncio - ERROR - Task exception was never retrieved
future: <Task finished coro=<Tester.test_single_proxy() done, defined at /home/python/Desktop/spider3/ProxyPool/proxypool/tester.py:20> exception=TypeError('%d format: a number is required, not NoneType',)>
Traceback (most recent call last):
  File "/home/python/Desktop/spider3/ProxyPool/proxypool/tester.py", line 35, in test_single_proxy
    async with session.get(TEST_URL, proxy=real_proxy, timeout=5, allow_redirects=False) as response:
  File "/home/python/.virtualenvs/Env1/lib/python3.5/site-packages/aiohttp/client.py", line 690, in __aenter__
    self._resp = yield from self._coro
  File "/home/python/.virtualenvs/Env1/lib/python3.5/site-packages/aiohttp/client.py", line 341, in _request
    break
  File "/home/python/.virtualenvs/Env1/lib/python3.5/site-packages/aiohttp/helpers.py", line 732, in __exit__
    raise asyncio.TimeoutError from None
concurrent.futures._base.TimeoutError

During handling of the above exception, another exception occurred:

Traceback (most recent call last):
  File "/usr/lib/python3.5/asyncio/tasks.py", line 241, in _step
    result = coro.throw(exc)
  File "/home/python/Desktop/spider3/ProxyPool/proxypool/tester.py", line 44, in test_single_proxy
    self.redis.decrease(proxy)
  File "/home/python/Desktop/spider3/ProxyPool/proxypool/db.py", line 77, in decrease
    logger.info('代理%s, 当前分数%d移除' % (proxy, score))
TypeError: %d format: a number is required, not NoneType
2018-09-21 18:55:44,848 - asyncio - ERROR - Task exception was never retrieved
future: <Task finished coro=<Tester.test_single_proxy() done, defined at /home/python/Desktop/spider3/ProxyPool/proxypool/tester.py:20> exception=TypeError('%d format: a number is required, not NoneType',)>
Traceback (most recent call last):
  File "/home/python/Desktop/spider3/ProxyPool/proxypool/tester.py", line 35, in test_single_proxy
    async with session.get(TEST_URL, proxy=real_proxy, timeout=5, allow_redirects=False) as response:
  File "/home/python/.virtualenvs/Env1/lib/python3.5/site-packages/aiohttp/client.py", line 690, in __aenter__
    self._resp = yield from self._coro
  File "/home/python/.virtualenvs/Env1/lib/python3.5/site-packages/aiohttp/client.py", line 341, in _request
    break
  File "/home/python/.virtualenvs/Env1/lib/python3.5/site-packages/aiohttp/helpers.py", line 732, in __exit__
    raise asyncio.TimeoutError from None
concurrent.futures._base.TimeoutError

During handling of the above exception, another exception occurred:

Traceback (most recent call last):
  File "/usr/lib/python3.5/asyncio/tasks.py", line 241, in _step
    result = coro.throw(exc)
  File "/home/python/Desktop/spider3/ProxyPool/proxypool/tester.py", line 44, in test_single_proxy
    self.redis.decrease(proxy)
  File "/home/python/Desktop/spider3/ProxyPool/proxypool/db.py", line 77, in decrease
    logger.info('代理%s, 当前分数%d移除' % (proxy, score))
TypeError: %d format: a number is required, not NoneType
2018-09-21 18:55:44,849 - asyncio - ERROR - Task exception was never retrieved
future: <Task finished coro=<Tester.test_single_proxy() done, defined at /home/python/Desktop/spider3/ProxyPool/proxypool/tester.py:20> exception=TypeError('%d format: a number is required, not NoneType',)>
Traceback (most recent call last):
  File "/home/python/Desktop/spider3/ProxyPool/proxypool/tester.py", line 35, in test_single_proxy
    async with session.get(TEST_URL, proxy=real_proxy, timeout=5, allow_redirects=False) as response:
  File "/home/python/.virtualenvs/Env1/lib/python3.5/site-packages/aiohttp/client.py", line 690, in __aenter__
    self._resp = yield from self._coro
  File "/home/python/.virtualenvs/Env1/lib/python3.5/site-packages/aiohttp/client.py", line 341, in _request
    break
  File "/home/python/.virtualenvs/Env1/lib/python3.5/site-packages/aiohttp/helpers.py", line 732, in __exit__
    raise asyncio.TimeoutError from None
concurrent.futures._base.TimeoutError

During handling of the above exception, another exception occurred:

Traceback (most recent call last):
  File "/usr/lib/python3.5/asyncio/tasks.py", line 241, in _step
    result = coro.throw(exc)
  File "/home/python/Desktop/spider3/ProxyPool/proxypool/tester.py", line 44, in test_single_proxy
    self.redis.decrease(proxy)
  File "/home/python/Desktop/spider3/ProxyPool/proxypool/db.py", line 77, in decrease
    logger.info('代理%s, 当前分数%d移除' % (proxy, score))
TypeError: %d format: a number is required, not NoneType
2018-09-21 18:55:44,849 - asyncio - ERROR - Task exception was never retrieved
future: <Task finished coro=<Tester.test_single_proxy() done, defined at /home/python/Desktop/spider3/ProxyPool/proxypool/tester.py:20> exception=TypeError('%d format: a number is required, not NoneType',)>
Traceback (most recent call last):
  File "/home/python/Desktop/spider3/ProxyPool/proxypool/tester.py", line 35, in test_single_proxy
    async with session.get(TEST_URL, proxy=real_proxy, timeout=5, allow_redirects=False) as response:
  File "/home/python/.virtualenvs/Env1/lib/python3.5/site-packages/aiohttp/client.py", line 690, in __aenter__
    self._resp = yield from self._coro
  File "/home/python/.virtualenvs/Env1/lib/python3.5/site-packages/aiohttp/client.py", line 341, in _request
    break
  File "/home/python/.virtualenvs/Env1/lib/python3.5/site-packages/aiohttp/helpers.py", line 732, in __exit__
    raise asyncio.TimeoutError from None
concurrent.futures._base.TimeoutError

During handling of the above exception, another exception occurred:

Traceback (most recent call last):
  File "/usr/lib/python3.5/asyncio/tasks.py", line 241, in _step
    result = coro.throw(exc)
  File "/home/python/Desktop/spider3/ProxyPool/proxypool/tester.py", line 44, in test_single_proxy
    self.redis.decrease(proxy)
  File "/home/python/Desktop/spider3/ProxyPool/proxypool/db.py", line 77, in decrease
    logger.info('代理%s, 当前分数%d移除' % (proxy, score))
TypeError: %d format: a number is required, not NoneType
2018-09-21 18:55:44,850 - asyncio - ERROR - Task exception was never retrieved
future: <Task finished coro=<Tester.test_single_proxy() done, defined at /home/python/Desktop/spider3/ProxyPool/proxypool/tester.py:20> exception=TypeError('%d format: a number is required, not NoneType',)>
Traceback (most recent call last):
  File "/home/python/Desktop/spider3/ProxyPool/proxypool/tester.py", line 35, in test_single_proxy
    async with session.get(TEST_URL, proxy=real_proxy, timeout=5, allow_redirects=False) as response:
  File "/home/python/.virtualenvs/Env1/lib/python3.5/site-packages/aiohttp/client.py", line 690, in __aenter__
    self._resp = yield from self._coro
  File "/home/python/.virtualenvs/Env1/lib/python3.5/site-packages/aiohttp/client.py", line 341, in _request
    break
  File "/home/python/.virtualenvs/Env1/lib/python3.5/site-packages/aiohttp/helpers.py", line 732, in __exit__
    raise asyncio.TimeoutError from None
concurrent.futures._base.TimeoutError

During handling of the above exception, another exception occurred:

Traceback (most recent call last):
  File "/usr/lib/python3.5/asyncio/tasks.py", line 241, in _step
    result = coro.throw(exc)
  File "/home/python/Desktop/spider3/ProxyPool/proxypool/tester.py", line 44, in test_single_proxy
    self.redis.decrease(proxy)
  File "/home/python/Desktop/spider3/ProxyPool/proxypool/db.py", line 77, in decrease
    logger.info('代理%s, 当前分数%d移除' % (proxy, score))
TypeError: %d format: a number is required, not NoneType
2018-09-21 18:55:44,850 - asyncio - ERROR - Task exception was never retrieved
future: <Task finished coro=<Tester.test_single_proxy() done, defined at /home/python/Desktop/spider3/ProxyPool/proxypool/tester.py:20> exception=TypeError('%d format: a number is required, not NoneType',)>
Traceback (most recent call last):
  File "/home/python/Desktop/spider3/ProxyPool/proxypool/tester.py", line 35, in test_single_proxy
    async with session.get(TEST_URL, proxy=real_proxy, timeout=5, allow_redirects=False) as response:
  File "/home/python/.virtualenvs/Env1/lib/python3.5/site-packages/aiohttp/client.py", line 690, in __aenter__
    self._resp = yield from self._coro
  File "/home/python/.virtualenvs/Env1/lib/python3.5/site-packages/aiohttp/client.py", line 341, in _request
    break
  File "/home/python/.virtualenvs/Env1/lib/python3.5/site-packages/aiohttp/helpers.py", line 732, in __exit__
    raise asyncio.TimeoutError from None
concurrent.futures._base.TimeoutError

During handling of the above exception, another exception occurred:

Traceback (most recent call last):
  File "/usr/lib/python3.5/asyncio/tasks.py", line 241, in _step
    result = coro.throw(exc)
  File "/home/python/Desktop/spider3/ProxyPool/proxypool/tester.py", line 44, in test_single_proxy
    self.redis.decrease(proxy)
  File "/home/python/Desktop/spider3/ProxyPool/proxypool/db.py", line 77, in decrease
    logger.info('代理%s, 当前分数%d移除' % (proxy, score))
TypeError: %d format: a number is required, not NoneType
2018-09-21 18:55:44,851 - asyncio - ERROR - Task exception was never retrieved
future: <Task finished coro=<Tester.test_single_proxy() done, defined at /home/python/Desktop/spider3/ProxyPool/proxypool/tester.py:20> exception=TypeError('%d format: a number is required, not NoneType',)>
Traceback (most recent call last):
  File "/home/python/Desktop/spider3/ProxyPool/proxypool/tester.py", line 35, in test_single_proxy
    async with session.get(TEST_URL, proxy=real_proxy, timeout=5, allow_redirects=False) as response:
  File "/home/python/.virtualenvs/Env1/lib/python3.5/site-packages/aiohttp/client.py", line 690, in __aenter__
    self._resp = yield from self._coro
  File "/home/python/.virtualenvs/Env1/lib/python3.5/site-packages/aiohttp/client.py", line 341, in _request
    break
  File "/home/python/.virtualenvs/Env1/lib/python3.5/site-packages/aiohttp/helpers.py", line 732, in __exit__
    raise asyncio.TimeoutError from None
concurrent.futures._base.TimeoutError

During handling of the above exception, another exception occurred:

Traceback (most recent call last):
  File "/usr/lib/python3.5/asyncio/tasks.py", line 241, in _step
    result = coro.throw(exc)
  File "/home/python/Desktop/spider3/ProxyPool/proxypool/tester.py", line 44, in test_single_proxy
    self.redis.decrease(proxy)
  File "/home/python/Desktop/spider3/ProxyPool/proxypool/db.py", line 77, in decrease
    logger.info('代理%s, 当前分数%d移除' % (proxy, score))
TypeError: %d format: a number is required, not NoneType
2018-09-21 18:55:44,851 - asyncio - ERROR - Task exception was never retrieved
future: <Task finished coro=<Tester.test_single_proxy() done, defined at /home/python/Desktop/spider3/ProxyPool/proxypool/tester.py:20> exception=TypeError('%d format: a number is required, not NoneType',)>
Traceback (most recent call last):
  File "/home/python/Desktop/spider3/ProxyPool/proxypool/tester.py", line 35, in test_single_proxy
    async with session.get(TEST_URL, proxy=real_proxy, timeout=5, allow_redirects=False) as response:
  File "/home/python/.virtualenvs/Env1/lib/python3.5/site-packages/aiohttp/client.py", line 690, in __aenter__
    self._resp = yield from self._coro
  File "/home/python/.virtualenvs/Env1/lib/python3.5/site-packages/aiohttp/client.py", line 341, in _request
    break
  File "/home/python/.virtualenvs/Env1/lib/python3.5/site-packages/aiohttp/helpers.py", line 732, in __exit__
    raise asyncio.TimeoutError from None
concurrent.futures._base.TimeoutError

During handling of the above exception, another exception occurred:

Traceback (most recent call last):
  File "/usr/lib/python3.5/asyncio/tasks.py", line 241, in _step
    result = coro.throw(exc)
  File "/home/python/Desktop/spider3/ProxyPool/proxypool/tester.py", line 44, in test_single_proxy
    self.redis.decrease(proxy)
  File "/home/python/Desktop/spider3/ProxyPool/proxypool/db.py", line 77, in decrease
    logger.info('代理%s, 当前分数%d移除' % (proxy, score))
TypeError: %d format: a number is required, not NoneType
2018-09-21 18:55:44,852 - asyncio - ERROR - Task exception was never retrieved
future: <Task finished coro=<Tester.test_single_proxy() done, defined at /home/python/Desktop/spider3/ProxyPool/proxypool/tester.py:20> exception=TypeError('%d format: a number is required, not NoneType',)>
Traceback (most recent call last):
  File "/home/python/Desktop/spider3/ProxyPool/proxypool/tester.py", line 35, in test_single_proxy
    async with session.get(TEST_URL, proxy=real_proxy, timeout=5, allow_redirects=False) as response:
  File "/home/python/.virtualenvs/Env1/lib/python3.5/site-packages/aiohttp/client.py", line 690, in __aenter__
    self._resp = yield from self._coro
  File "/home/python/.virtualenvs/Env1/lib/python3.5/site-packages/aiohttp/client.py", line 341, in _request
    break
  File "/home/python/.virtualenvs/Env1/lib/python3.5/site-packages/aiohttp/helpers.py", line 732, in __exit__
    raise asyncio.TimeoutError from None
concurrent.futures._base.TimeoutError

During handling of the above exception, another exception occurred:

Traceback (most recent call last):
  File "/usr/lib/python3.5/asyncio/tasks.py", line 241, in _step
    result = coro.throw(exc)
  File "/home/python/Desktop/spider3/ProxyPool/proxypool/tester.py", line 44, in test_single_proxy
    self.redis.decrease(proxy)
  File "/home/python/Desktop/spider3/ProxyPool/proxypool/db.py", line 77, in decrease
    logger.info('代理%s, 当前分数%d移除' % (proxy, score))
TypeError: %d format: a number is required, not NoneType
2018-09-21 19:00:41,707 - tester - ERROR - 测试器发生错误Set of coroutines/Futures is empty.
Traceback (most recent call last):
  File "/home/python/Desktop/spider3/ProxyPool/proxypool/tester.py", line 66, in run
    loop.run_until_complete(asyncio.wait(tasks))
  File "/usr/lib/python3.5/asyncio/base_events.py", line 387, in run_until_complete
    return future.result()
  File "/usr/lib/python3.5/asyncio/futures.py", line 274, in result
    raise self._exception
  File "/usr/lib/python3.5/asyncio/tasks.py", line 239, in _step
    result = coro.send(None)
  File "/usr/lib/python3.5/asyncio/tasks.py", line 338, in wait
    raise ValueError('Set of coroutines/Futures is empty.')
ValueError: Set of coroutines/Futures is empty.
2018-09-21 19:05:50,704 - tester - ERROR - 测试器发生错误Set of coroutines/Futures is empty.
Traceback (most recent call last):
  File "/home/python/Desktop/spider3/ProxyPool/proxypool/tester.py", line 66, in run
    loop.run_until_complete(asyncio.wait(tasks))
  File "/usr/lib/python3.5/asyncio/base_events.py", line 387, in run_until_complete
    return future.result()
  File "/usr/lib/python3.5/asyncio/futures.py", line 274, in result
    raise self._exception
  File "/usr/lib/python3.5/asyncio/tasks.py", line 239, in _step
    result = coro.send(None)
  File "/usr/lib/python3.5/asyncio/tasks.py", line 338, in wait
    raise ValueError('Set of coroutines/Futures is empty.')
ValueError: Set of coroutines/Futures is empty.
2018-09-21 19:09:42,712 - tester - ERROR - 测试器发生错误Set of coroutines/Futures is empty.
Traceback (most recent call last):
  File "/home/python/Desktop/spider3/ProxyPool/proxypool/tester.py", line 66, in run
    loop.run_until_complete(asyncio.wait(tasks))
  File "/usr/lib/python3.5/asyncio/base_events.py", line 387, in run_until_complete
    return future.result()
  File "/usr/lib/python3.5/asyncio/futures.py", line 274, in result
    raise self._exception
  File "/usr/lib/python3.5/asyncio/tasks.py", line 239, in _step
    result = coro.send(None)
  File "/usr/lib/python3.5/asyncio/tasks.py", line 338, in wait
    raise ValueError('Set of coroutines/Futures is empty.')
ValueError: Set of coroutines/Futures is empty.
2018-09-21 19:11:55,782 - asyncio - ERROR - Task exception was never retrieved
future: <Task finished coro=<Tester.test_single_proxy() done, defined at /home/python/Desktop/spider3/ProxyPool/proxypool/tester.py:20> exception=TypeError('%d format: a number is required, not NoneType',)>
Traceback (most recent call last):
  File "/home/python/Desktop/spider3/ProxyPool/proxypool/tester.py", line 35, in test_single_proxy
    async with session.get(TEST_URL, proxy=real_proxy, timeout=5, allow_redirects=False) as response:
  File "/home/python/.virtualenvs/Env1/lib/python3.5/site-packages/aiohttp/client.py", line 690, in __aenter__
    self._resp = yield from self._coro
  File "/home/python/.virtualenvs/Env1/lib/python3.5/site-packages/aiohttp/client.py", line 341, in _request
    break
  File "/home/python/.virtualenvs/Env1/lib/python3.5/site-packages/aiohttp/helpers.py", line 732, in __exit__
    raise asyncio.TimeoutError from None
concurrent.futures._base.TimeoutError

During handling of the above exception, another exception occurred:

Traceback (most recent call last):
  File "/usr/lib/python3.5/asyncio/tasks.py", line 241, in _step
    result = coro.throw(exc)
  File "/home/python/Desktop/spider3/ProxyPool/proxypool/tester.py", line 44, in test_single_proxy
    self.redis.decrease(proxy)
  File "/home/python/Desktop/spider3/ProxyPool/proxypool/db.py", line 77, in decrease
    logger.info('代理%s, 当前分数%d移除' % (proxy, score))
TypeError: %d format: a number is required, not NoneType
2018-09-21 19:11:55,783 - asyncio - ERROR - Task exception was never retrieved
future: <Task finished coro=<Tester.test_single_proxy() done, defined at /home/python/Desktop/spider3/ProxyPool/proxypool/tester.py:20> exception=TypeError('%d format: a number is required, not NoneType',)>
Traceback (most recent call last):
  File "/home/python/Desktop/spider3/ProxyPool/proxypool/tester.py", line 35, in test_single_proxy
    async with session.get(TEST_URL, proxy=real_proxy, timeout=5, allow_redirects=False) as response:
  File "/home/python/.virtualenvs/Env1/lib/python3.5/site-packages/aiohttp/client.py", line 690, in __aenter__
    self._resp = yield from self._coro
  File "/home/python/.virtualenvs/Env1/lib/python3.5/site-packages/aiohttp/client.py", line 341, in _request
    break
  File "/home/python/.virtualenvs/Env1/lib/python3.5/site-packages/aiohttp/helpers.py", line 732, in __exit__
    raise asyncio.TimeoutError from None
concurrent.futures._base.TimeoutError

During handling of the above exception, another exception occurred:

Traceback (most recent call last):
  File "/usr/lib/python3.5/asyncio/tasks.py", line 241, in _step
    result = coro.throw(exc)
  File "/home/python/Desktop/spider3/ProxyPool/proxypool/tester.py", line 44, in test_single_proxy
    self.redis.decrease(proxy)
  File "/home/python/Desktop/spider3/ProxyPool/proxypool/db.py", line 77, in decrease
    logger.info('代理%s, 当前分数%d移除' % (proxy, score))
TypeError: %d format: a number is required, not NoneType
2018-09-21 19:11:55,783 - asyncio - ERROR - Task exception was never retrieved
future: <Task finished coro=<Tester.test_single_proxy() done, defined at /home/python/Desktop/spider3/ProxyPool/proxypool/tester.py:20> exception=TypeError('%d format: a number is required, not NoneType',)>
Traceback (most recent call last):
  File "/home/python/Desktop/spider3/ProxyPool/proxypool/tester.py", line 35, in test_single_proxy
    async with session.get(TEST_URL, proxy=real_proxy, timeout=5, allow_redirects=False) as response:
  File "/home/python/.virtualenvs/Env1/lib/python3.5/site-packages/aiohttp/client.py", line 690, in __aenter__
    self._resp = yield from self._coro
  File "/home/python/.virtualenvs/Env1/lib/python3.5/site-packages/aiohttp/client.py", line 341, in _request
    break
  File "/home/python/.virtualenvs/Env1/lib/python3.5/site-packages/aiohttp/helpers.py", line 732, in __exit__
    raise asyncio.TimeoutError from None
concurrent.futures._base.TimeoutError

During handling of the above exception, another exception occurred:

Traceback (most recent call last):
  File "/usr/lib/python3.5/asyncio/tasks.py", line 241, in _step
    result = coro.throw(exc)
  File "/home/python/Desktop/spider3/ProxyPool/proxypool/tester.py", line 44, in test_single_proxy
    self.redis.decrease(proxy)
  File "/home/python/Desktop/spider3/ProxyPool/proxypool/db.py", line 77, in decrease
    logger.info('代理%s, 当前分数%d移除' % (proxy, score))
TypeError: %d format: a number is required, not NoneType
2018-09-21 19:11:55,784 - asyncio - ERROR - Task exception was never retrieved
future: <Task finished coro=<Tester.test_single_proxy() done, defined at /home/python/Desktop/spider3/ProxyPool/proxypool/tester.py:20> exception=TypeError('%d format: a number is required, not NoneType',)>
Traceback (most recent call last):
  File "/home/python/Desktop/spider3/ProxyPool/proxypool/tester.py", line 35, in test_single_proxy
    async with session.get(TEST_URL, proxy=real_proxy, timeout=5, allow_redirects=False) as response:
  File "/home/python/.virtualenvs/Env1/lib/python3.5/site-packages/aiohttp/client.py", line 690, in __aenter__
    self._resp = yield from self._coro
  File "/home/python/.virtualenvs/Env1/lib/python3.5/site-packages/aiohttp/client.py", line 341, in _request
    break
  File "/home/python/.virtualenvs/Env1/lib/python3.5/site-packages/aiohttp/helpers.py", line 732, in __exit__
    raise asyncio.TimeoutError from None
concurrent.futures._base.TimeoutError

During handling of the above exception, another exception occurred:

Traceback (most recent call last):
  File "/usr/lib/python3.5/asyncio/tasks.py", line 241, in _step
    result = coro.throw(exc)
  File "/home/python/Desktop/spider3/ProxyPool/proxypool/tester.py", line 44, in test_single_proxy
    self.redis.decrease(proxy)
  File "/home/python/Desktop/spider3/ProxyPool/proxypool/db.py", line 77, in decrease
    logger.info('代理%s, 当前分数%d移除' % (proxy, score))
TypeError: %d format: a number is required, not NoneType
2018-09-21 19:11:55,784 - asyncio - ERROR - Task exception was never retrieved
future: <Task finished coro=<Tester.test_single_proxy() done, defined at /home/python/Desktop/spider3/ProxyPool/proxypool/tester.py:20> exception=TypeError('%d format: a number is required, not NoneType',)>
Traceback (most recent call last):
  File "/home/python/Desktop/spider3/ProxyPool/proxypool/tester.py", line 35, in test_single_proxy
    async with session.get(TEST_URL, proxy=real_proxy, timeout=5, allow_redirects=False) as response:
  File "/home/python/.virtualenvs/Env1/lib/python3.5/site-packages/aiohttp/client.py", line 690, in __aenter__
    self._resp = yield from self._coro
  File "/home/python/.virtualenvs/Env1/lib/python3.5/site-packages/aiohttp/client.py", line 267, in _request
    conn = yield from self._connector.connect(req)
  File "/home/python/.virtualenvs/Env1/lib/python3.5/site-packages/aiohttp/connector.py", line 402, in connect
    proto = yield from self._create_connection(req)
  File "/home/python/.virtualenvs/Env1/lib/python3.5/site-packages/aiohttp/connector.py", line 747, in _create_connection
    _, proto = yield from self._create_proxy_connection(req)
  File "/home/python/.virtualenvs/Env1/lib/python3.5/site-packages/aiohttp/connector.py", line 906, in _create_proxy_connection
    resp = yield from proxy_resp.start(conn, True)
  File "/home/python/.virtualenvs/Env1/lib/python3.5/site-packages/aiohttp/client_reqrep.py", line 624, in start
    (message, payload) = yield from self._protocol.read()
  File "/home/python/.virtualenvs/Env1/lib/python3.5/site-packages/aiohttp/streams.py", line 554, in read
    yield from self._waiter
  File "/usr/lib/python3.5/asyncio/futures.py", line 361, in __iter__
    yield self  # This tells Task to wait for completion.
  File "/usr/lib/python3.5/asyncio/tasks.py", line 296, in _wakeup
    future.result()
  File "/usr/lib/python3.5/asyncio/futures.py", line 274, in result
    raise self._exception
aiohttp.client_exceptions.ClientOSError: [Errno 104] Connection reset by peer

During handling of the above exception, another exception occurred:

Traceback (most recent call last):
  File "/usr/lib/python3.5/asyncio/tasks.py", line 241, in _step
    result = coro.throw(exc)
  File "/home/python/Desktop/spider3/ProxyPool/proxypool/tester.py", line 44, in test_single_proxy
    self.redis.decrease(proxy)
  File "/home/python/Desktop/spider3/ProxyPool/proxypool/db.py", line 77, in decrease
    logger.info('代理%s, 当前分数%d移除' % (proxy, score))
TypeError: %d format: a number is required, not NoneType
2018-09-21 19:11:55,785 - asyncio - ERROR - Task exception was never retrieved
future: <Task finished coro=<Tester.test_single_proxy() done, defined at /home/python/Desktop/spider3/ProxyPool/proxypool/tester.py:20> exception=TypeError('%d format: a number is required, not NoneType',)>
Traceback (most recent call last):
  File "/home/python/.virtualenvs/Env1/lib/python3.5/site-packages/aiohttp/connector.py", line 797, in _wrap_create_connection
    return (yield from self._loop.create_connection(*args, **kwargs))
  File "/usr/lib/python3.5/asyncio/base_events.py", line 695, in create_connection
    raise exceptions[0]
  File "/usr/lib/python3.5/asyncio/base_events.py", line 682, in create_connection
    yield from self.sock_connect(sock, address)
  File "/usr/lib/python3.5/asyncio/selector_events.py", line 402, in sock_connect
    return (yield from fut)
  File "/usr/lib/python3.5/asyncio/futures.py", line 361, in __iter__
    yield self  # This tells Task to wait for completion.
  File "/usr/lib/python3.5/asyncio/tasks.py", line 296, in _wakeup
    future.result()
  File "/usr/lib/python3.5/asyncio/futures.py", line 274, in result
    raise self._exception
  File "/usr/lib/python3.5/asyncio/selector_events.py", line 432, in _sock_connect_cb
    raise OSError(err, 'Connect call failed %s' % (address,))
ConnectionRefusedError: [Errno 111] Connect call failed ('125.115.180.210', 3128)

The above exception was the direct cause of the following exception:

Traceback (most recent call last):
  File "/home/python/Desktop/spider3/ProxyPool/proxypool/tester.py", line 35, in test_single_proxy
    async with session.get(TEST_URL, proxy=real_proxy, timeout=5, allow_redirects=False) as response:
  File "/home/python/.virtualenvs/Env1/lib/python3.5/site-packages/aiohttp/client.py", line 690, in __aenter__
    self._resp = yield from self._coro
  File "/home/python/.virtualenvs/Env1/lib/python3.5/site-packages/aiohttp/client.py", line 267, in _request
    conn = yield from self._connector.connect(req)
  File "/home/python/.virtualenvs/Env1/lib/python3.5/site-packages/aiohttp/connector.py", line 402, in connect
    proto = yield from self._create_connection(req)
  File "/home/python/.virtualenvs/Env1/lib/python3.5/site-packages/aiohttp/connector.py", line 747, in _create_connection
    _, proto = yield from self._create_proxy_connection(req)
  File "/home/python/.virtualenvs/Env1/lib/python3.5/site-packages/aiohttp/connector.py", line 880, in _create_proxy_connection
    proxy_req, client_error=ClientProxyConnectionError)
  File "/home/python/.virtualenvs/Env1/lib/python3.5/site-packages/aiohttp/connector.py", line 860, in _create_direct_connection
    raise last_exc
  File "/home/python/.virtualenvs/Env1/lib/python3.5/site-packages/aiohttp/connector.py", line 832, in _create_direct_connection
    req=req, client_error=client_error)
  File "/home/python/.virtualenvs/Env1/lib/python3.5/site-packages/aiohttp/connector.py", line 804, in _wrap_create_connection
    raise client_error(req.connection_key, exc) from exc
aiohttp.client_exceptions.ClientProxyConnectionError: Cannot connect to host 125.115.180.210:3128 ssl:False [Connect call failed ('125.115.180.210', 3128)]

During handling of the above exception, another exception occurred:

Traceback (most recent call last):
  File "/usr/lib/python3.5/asyncio/tasks.py", line 241, in _step
    result = coro.throw(exc)
  File "/home/python/Desktop/spider3/ProxyPool/proxypool/tester.py", line 44, in test_single_proxy
    self.redis.decrease(proxy)
  File "/home/python/Desktop/spider3/ProxyPool/proxypool/db.py", line 77, in decrease
    logger.info('代理%s, 当前分数%d移除' % (proxy, score))
TypeError: %d format: a number is required, not NoneType
2018-09-21 19:11:55,785 - asyncio - ERROR - Task exception was never retrieved
future: <Task finished coro=<Tester.test_single_proxy() done, defined at /home/python/Desktop/spider3/ProxyPool/proxypool/tester.py:20> exception=TypeError('%d format: a number is required, not NoneType',)>
Traceback (most recent call last):
  File "/home/python/Desktop/spider3/ProxyPool/proxypool/tester.py", line 35, in test_single_proxy
    async with session.get(TEST_URL, proxy=real_proxy, timeout=5, allow_redirects=False) as response:
  File "/home/python/.virtualenvs/Env1/lib/python3.5/site-packages/aiohttp/client.py", line 690, in __aenter__
    self._resp = yield from self._coro
  File "/home/python/.virtualenvs/Env1/lib/python3.5/site-packages/aiohttp/client.py", line 341, in _request
    break
  File "/home/python/.virtualenvs/Env1/lib/python3.5/site-packages/aiohttp/helpers.py", line 732, in __exit__
    raise asyncio.TimeoutError from None
concurrent.futures._base.TimeoutError

During handling of the above exception, another exception occurred:

Traceback (most recent call last):
  File "/usr/lib/python3.5/asyncio/tasks.py", line 241, in _step
    result = coro.throw(exc)
  File "/home/python/Desktop/spider3/ProxyPool/proxypool/tester.py", line 44, in test_single_proxy
    self.redis.decrease(proxy)
  File "/home/python/Desktop/spider3/ProxyPool/proxypool/db.py", line 77, in decrease
    logger.info('代理%s, 当前分数%d移除' % (proxy, score))
TypeError: %d format: a number is required, not NoneType
2018-09-21 19:11:55,786 - asyncio - ERROR - Task exception was never retrieved
future: <Task finished coro=<Tester.test_single_proxy() done, defined at /home/python/Desktop/spider3/ProxyPool/proxypool/tester.py:20> exception=TypeError('%d format: a number is required, not NoneType',)>
Traceback (most recent call last):
  File "/home/python/Desktop/spider3/ProxyPool/proxypool/tester.py", line 35, in test_single_proxy
    async with session.get(TEST_URL, proxy=real_proxy, timeout=5, allow_redirects=False) as response:
  File "/home/python/.virtualenvs/Env1/lib/python3.5/site-packages/aiohttp/client.py", line 690, in __aenter__
    self._resp = yield from self._coro
  File "/home/python/.virtualenvs/Env1/lib/python3.5/site-packages/aiohttp/client.py", line 267, in _request
    conn = yield from self._connector.connect(req)
  File "/home/python/.virtualenvs/Env1/lib/python3.5/site-packages/aiohttp/connector.py", line 402, in connect
    proto = yield from self._create_connection(req)
  File "/home/python/.virtualenvs/Env1/lib/python3.5/site-packages/aiohttp/connector.py", line 747, in _create_connection
    _, proto = yield from self._create_proxy_connection(req)
  File "/home/python/.virtualenvs/Env1/lib/python3.5/site-packages/aiohttp/connector.py", line 921, in _create_proxy_connection
    headers=resp.headers)
aiohttp.client_exceptions.ClientHttpProxyError: 500, message='Internal Server Error'

During handling of the above exception, another exception occurred:

Traceback (most recent call last):
  File "/usr/lib/python3.5/asyncio/tasks.py", line 239, in _step
    result = coro.send(None)
  File "/home/python/Desktop/spider3/ProxyPool/proxypool/tester.py", line 44, in test_single_proxy
    self.redis.decrease(proxy)
  File "/home/python/Desktop/spider3/ProxyPool/proxypool/db.py", line 77, in decrease
    logger.info('代理%s, 当前分数%d移除' % (proxy, score))
TypeError: %d format: a number is required, not NoneType
2018-09-21 19:11:55,786 - asyncio - ERROR - Task exception was never retrieved
future: <Task finished coro=<Tester.test_single_proxy() done, defined at /home/python/Desktop/spider3/ProxyPool/proxypool/tester.py:20> exception=TypeError('%d format: a number is required, not NoneType',)>
Traceback (most recent call last):
  File "/home/python/Desktop/spider3/ProxyPool/proxypool/tester.py", line 35, in test_single_proxy
    async with session.get(TEST_URL, proxy=real_proxy, timeout=5, allow_redirects=False) as response:
  File "/home/python/.virtualenvs/Env1/lib/python3.5/site-packages/aiohttp/client.py", line 690, in __aenter__
    self._resp = yield from self._coro
  File "/home/python/.virtualenvs/Env1/lib/python3.5/site-packages/aiohttp/client.py", line 267, in _request
    conn = yield from self._connector.connect(req)
  File "/home/python/.virtualenvs/Env1/lib/python3.5/site-packages/aiohttp/connector.py", line 402, in connect
    proto = yield from self._create_connection(req)
  File "/home/python/.virtualenvs/Env1/lib/python3.5/site-packages/aiohttp/connector.py", line 747, in _create_connection
    _, proto = yield from self._create_proxy_connection(req)
  File "/home/python/.virtualenvs/Env1/lib/python3.5/site-packages/aiohttp/connector.py", line 906, in _create_proxy_connection
    resp = yield from proxy_resp.start(conn, True)
  File "/home/python/.virtualenvs/Env1/lib/python3.5/site-packages/aiohttp/client_reqrep.py", line 624, in start
    (message, payload) = yield from self._protocol.read()
  File "/home/python/.virtualenvs/Env1/lib/python3.5/site-packages/aiohttp/streams.py", line 554, in read
    yield from self._waiter
  File "/usr/lib/python3.5/asyncio/futures.py", line 361, in __iter__
    yield self  # This tells Task to wait for completion.
  File "/usr/lib/python3.5/asyncio/tasks.py", line 296, in _wakeup
    future.result()
  File "/usr/lib/python3.5/asyncio/futures.py", line 274, in result
    raise self._exception
aiohttp.client_exceptions.ClientOSError: [Errno 104] Connection reset by peer

During handling of the above exception, another exception occurred:

Traceback (most recent call last):
  File "/usr/lib/python3.5/asyncio/tasks.py", line 241, in _step
    result = coro.throw(exc)
  File "/home/python/Desktop/spider3/ProxyPool/proxypool/tester.py", line 44, in test_single_proxy
    self.redis.decrease(proxy)
  File "/home/python/Desktop/spider3/ProxyPool/proxypool/db.py", line 77, in decrease
    logger.info('代理%s, 当前分数%d移除' % (proxy, score))
TypeError: %d format: a number is required, not NoneType
2018-09-21 19:13:01,708 - tester - ERROR - 测试器发生错误Set of coroutines/Futures is empty.
Traceback (most recent call last):
  File "/home/python/Desktop/spider3/ProxyPool/proxypool/tester.py", line 66, in run
    loop.run_until_complete(asyncio.wait(tasks))
  File "/usr/lib/python3.5/asyncio/base_events.py", line 387, in run_until_complete
    return future.result()
  File "/usr/lib/python3.5/asyncio/futures.py", line 274, in result
    raise self._exception
  File "/usr/lib/python3.5/asyncio/tasks.py", line 239, in _step
    result = coro.send(None)
  File "/usr/lib/python3.5/asyncio/tasks.py", line 338, in wait
    raise ValueError('Set of coroutines/Futures is empty.')
ValueError: Set of coroutines/Futures is empty.
2018-09-21 19:15:47,722 - tester - ERROR - 测试器发生错误Set of coroutines/Futures is empty.
Traceback (most recent call last):
  File "/home/python/Desktop/spider3/ProxyPool/proxypool/tester.py", line 66, in run
    loop.run_until_complete(asyncio.wait(tasks))
  File "/usr/lib/python3.5/asyncio/base_events.py", line 387, in run_until_complete
    return future.result()
  File "/usr/lib/python3.5/asyncio/futures.py", line 274, in result
    raise self._exception
  File "/usr/lib/python3.5/asyncio/tasks.py", line 239, in _step
    result = coro.send(None)
  File "/usr/lib/python3.5/asyncio/tasks.py", line 338, in wait
    raise ValueError('Set of coroutines/Futures is empty.')
ValueError: Set of coroutines/Futures is empty.
2018-09-21 19:18:11,704 - tester - ERROR - 测试器发生错误Set of coroutines/Futures is empty.
Traceback (most recent call last):
  File "/home/python/Desktop/spider3/ProxyPool/proxypool/tester.py", line 66, in run
    loop.run_until_complete(asyncio.wait(tasks))
  File "/usr/lib/python3.5/asyncio/base_events.py", line 387, in run_until_complete
    return future.result()
  File "/usr/lib/python3.5/asyncio/futures.py", line 274, in result
    raise self._exception
  File "/usr/lib/python3.5/asyncio/tasks.py", line 239, in _step
    result = coro.send(None)
  File "/usr/lib/python3.5/asyncio/tasks.py", line 338, in wait
    raise ValueError('Set of coroutines/Futures is empty.')
ValueError: Set of coroutines/Futures is empty.
2018-09-21 19:20:24,709 - tester - ERROR - 测试器发生错误Set of coroutines/Futures is empty.
Traceback (most recent call last):
  File "/home/python/Desktop/spider3/ProxyPool/proxypool/tester.py", line 66, in run
    loop.run_until_complete(asyncio.wait(tasks))
  File "/usr/lib/python3.5/asyncio/base_events.py", line 387, in run_until_complete
    return future.result()
  File "/usr/lib/python3.5/asyncio/futures.py", line 274, in result
    raise self._exception
  File "/usr/lib/python3.5/asyncio/tasks.py", line 239, in _step
    result = coro.send(None)
  File "/usr/lib/python3.5/asyncio/tasks.py", line 338, in wait
    raise ValueError('Set of coroutines/Futures is empty.')
ValueError: Set of coroutines/Futures is empty.
2018-09-21 19:32:18,706 - tester - ERROR - 测试器发生错误Set of coroutines/Futures is empty.
Traceback (most recent call last):
  File "/home/python/Desktop/spider3/ProxyPool/proxypool/tester.py", line 66, in run
    loop.run_until_complete(asyncio.wait(tasks))
  File "/usr/lib/python3.5/asyncio/base_events.py", line 387, in run_until_complete
    return future.result()
  File "/usr/lib/python3.5/asyncio/futures.py", line 274, in result
    raise self._exception
  File "/usr/lib/python3.5/asyncio/tasks.py", line 239, in _step
    result = coro.send(None)
  File "/usr/lib/python3.5/asyncio/tasks.py", line 338, in wait
    raise ValueError('Set of coroutines/Futures is empty.')
ValueError: Set of coroutines/Futures is empty.
2018-09-21 21:39:15,704 - tester - ERROR - 测试器发生错误Set of coroutines/Futures is empty.
Traceback (most recent call last):
  File "/home/python/Desktop/spider3/ProxyPool/proxypool/tester.py", line 66, in run
    loop.run_until_complete(asyncio.wait(tasks))
  File "/usr/lib/python3.5/asyncio/base_events.py", line 387, in run_until_complete
    return future.result()
  File "/usr/lib/python3.5/asyncio/futures.py", line 274, in result
    raise self._exception
  File "/usr/lib/python3.5/asyncio/tasks.py", line 239, in _step
    result = coro.send(None)
  File "/usr/lib/python3.5/asyncio/tasks.py", line 338, in wait
    raise ValueError('Set of coroutines/Futures is empty.')
ValueError: Set of coroutines/Futures is empty.
2018-09-21 21:39:41,709 - tester - ERROR - 测试器发生错误Set of coroutines/Futures is empty.
Traceback (most recent call last):
  File "/home/python/Desktop/spider3/ProxyPool/proxypool/tester.py", line 66, in run
    loop.run_until_complete(asyncio.wait(tasks))
  File "/usr/lib/python3.5/asyncio/base_events.py", line 387, in run_until_complete
    return future.result()
  File "/usr/lib/python3.5/asyncio/futures.py", line 274, in result
    raise self._exception
  File "/usr/lib/python3.5/asyncio/tasks.py", line 239, in _step
    result = coro.send(None)
  File "/usr/lib/python3.5/asyncio/tasks.py", line 338, in wait
    raise ValueError('Set of coroutines/Futures is empty.')
ValueError: Set of coroutines/Futures is empty.
2018-09-21 21:45:41,698 - tester - ERROR - 测试器发生错误Set of coroutines/Futures is empty.
Traceback (most recent call last):
  File "/home/python/Desktop/spider3/ProxyPool/proxypool/tester.py", line 66, in run
    loop.run_until_complete(asyncio.wait(tasks))
  File "/usr/lib/python3.5/asyncio/base_events.py", line 387, in run_until_complete
    return future.result()
  File "/usr/lib/python3.5/asyncio/futures.py", line 274, in result
    raise self._exception
  File "/usr/lib/python3.5/asyncio/tasks.py", line 239, in _step
    result = coro.send(None)
  File "/usr/lib/python3.5/asyncio/tasks.py", line 338, in wait
    raise ValueError('Set of coroutines/Futures is empty.')
ValueError: Set of coroutines/Futures is empty.
2018-09-21 21:45:45,848 - tester - ERROR - 测试器发生错误Set of coroutines/Futures is empty.
Traceback (most recent call last):
  File "/home/python/Desktop/spider3/ProxyPool/proxypool/tester.py", line 66, in run
    loop.run_until_complete(asyncio.wait(tasks))
  File "/usr/lib/python3.5/asyncio/base_events.py", line 387, in run_until_complete
    return future.result()
  File "/usr/lib/python3.5/asyncio/futures.py", line 274, in result
    raise self._exception
  File "/usr/lib/python3.5/asyncio/tasks.py", line 239, in _step
    result = coro.send(None)
  File "/usr/lib/python3.5/asyncio/tasks.py", line 338, in wait
    raise ValueError('Set of coroutines/Futures is empty.')
ValueError: Set of coroutines/Futures is empty.
2018-09-21 21:53:13,712 - tester - ERROR - 测试器发生错误Set of coroutines/Futures is empty.
Traceback (most recent call last):
  File "/home/python/Desktop/spider3/ProxyPool/proxypool/tester.py", line 66, in run
    loop.run_until_complete(asyncio.wait(tasks))
  File "/usr/lib/python3.5/asyncio/base_events.py", line 387, in run_until_complete
    return future.result()
  File "/usr/lib/python3.5/asyncio/futures.py", line 274, in result
    raise self._exception
  File "/usr/lib/python3.5/asyncio/tasks.py", line 239, in _step
    result = coro.send(None)
  File "/usr/lib/python3.5/asyncio/tasks.py", line 338, in wait
    raise ValueError('Set of coroutines/Futures is empty.')
ValueError: Set of coroutines/Futures is empty.
2018-09-21 21:57:49,723 - asyncio - ERROR - Task exception was never retrieved
future: <Task finished coro=<Tester.test_single_proxy() done, defined at /home/python/Desktop/spider3/ProxyPool/proxypool/tester.py:20> exception=TypeError('%d format: a number is required, not NoneType',)>
Traceback (most recent call last):
  File "/home/python/Desktop/spider3/ProxyPool/proxypool/tester.py", line 35, in test_single_proxy
    async with session.get(TEST_URL, proxy=real_proxy, timeout=5, allow_redirects=False) as response:
  File "/home/python/.virtualenvs/Env1/lib/python3.5/site-packages/aiohttp/client.py", line 690, in __aenter__
    self._resp = yield from self._coro
  File "/home/python/.virtualenvs/Env1/lib/python3.5/site-packages/aiohttp/client.py", line 341, in _request
    break
  File "/home/python/.virtualenvs/Env1/lib/python3.5/site-packages/aiohttp/helpers.py", line 732, in __exit__
    raise asyncio.TimeoutError from None
concurrent.futures._base.TimeoutError

During handling of the above exception, another exception occurred:

Traceback (most recent call last):
  File "/usr/lib/python3.5/asyncio/tasks.py", line 241, in _step
    result = coro.throw(exc)
  File "/home/python/Desktop/spider3/ProxyPool/proxypool/tester.py", line 44, in test_single_proxy
    self.redis.decrease(proxy)
  File "/home/python/Desktop/spider3/ProxyPool/proxypool/db.py", line 77, in decrease
    logger.info('代理%s, 当前分数%d移除' % (proxy, score))
TypeError: %d format: a number is required, not NoneType
2018-09-21 21:57:49,724 - asyncio - ERROR - Task exception was never retrieved
future: <Task finished coro=<Tester.test_single_proxy() done, defined at /home/python/Desktop/spider3/ProxyPool/proxypool/tester.py:20> exception=TypeError('%d format: a number is required, not NoneType',)>
Traceback (most recent call last):
  File "/home/python/Desktop/spider3/ProxyPool/proxypool/tester.py", line 35, in test_single_proxy
    async with session.get(TEST_URL, proxy=real_proxy, timeout=5, allow_redirects=False) as response:
  File "/home/python/.virtualenvs/Env1/lib/python3.5/site-packages/aiohttp/client.py", line 690, in __aenter__
    self._resp = yield from self._coro
  File "/home/python/.virtualenvs/Env1/lib/python3.5/site-packages/aiohttp/client.py", line 341, in _request
    break
  File "/home/python/.virtualenvs/Env1/lib/python3.5/site-packages/aiohttp/helpers.py", line 732, in __exit__
    raise asyncio.TimeoutError from None
concurrent.futures._base.TimeoutError

During handling of the above exception, another exception occurred:

Traceback (most recent call last):
  File "/usr/lib/python3.5/asyncio/tasks.py", line 241, in _step
    result = coro.throw(exc)
  File "/home/python/Desktop/spider3/ProxyPool/proxypool/tester.py", line 44, in test_single_proxy
    self.redis.decrease(proxy)
  File "/home/python/Desktop/spider3/ProxyPool/proxypool/db.py", line 77, in decrease
    logger.info('代理%s, 当前分数%d移除' % (proxy, score))
TypeError: %d format: a number is required, not NoneType
2018-09-21 21:57:49,724 - asyncio - ERROR - Task exception was never retrieved
future: <Task finished coro=<Tester.test_single_proxy() done, defined at /home/python/Desktop/spider3/ProxyPool/proxypool/tester.py:20> exception=TypeError('%d format: a number is required, not NoneType',)>
Traceback (most recent call last):
  File "/home/python/Desktop/spider3/ProxyPool/proxypool/tester.py", line 35, in test_single_proxy
    async with session.get(TEST_URL, proxy=real_proxy, timeout=5, allow_redirects=False) as response:
  File "/home/python/.virtualenvs/Env1/lib/python3.5/site-packages/aiohttp/client.py", line 690, in __aenter__
    self._resp = yield from self._coro
  File "/home/python/.virtualenvs/Env1/lib/python3.5/site-packages/aiohttp/client.py", line 341, in _request
    break
  File "/home/python/.virtualenvs/Env1/lib/python3.5/site-packages/aiohttp/helpers.py", line 732, in __exit__
    raise asyncio.TimeoutError from None
concurrent.futures._base.TimeoutError

During handling of the above exception, another exception occurred:

Traceback (most recent call last):
  File "/usr/lib/python3.5/asyncio/tasks.py", line 241, in _step
    result = coro.throw(exc)
  File "/home/python/Desktop/spider3/ProxyPool/proxypool/tester.py", line 44, in test_single_proxy
    self.redis.decrease(proxy)
  File "/home/python/Desktop/spider3/ProxyPool/proxypool/db.py", line 77, in decrease
    logger.info('代理%s, 当前分数%d移除' % (proxy, score))
TypeError: %d format: a number is required, not NoneType
2018-09-21 21:57:49,724 - asyncio - ERROR - Task exception was never retrieved
future: <Task finished coro=<Tester.test_single_proxy() done, defined at /home/python/Desktop/spider3/ProxyPool/proxypool/tester.py:20> exception=TypeError('%d format: a number is required, not NoneType',)>
Traceback (most recent call last):
  File "/home/python/Desktop/spider3/ProxyPool/proxypool/tester.py", line 35, in test_single_proxy
    async with session.get(TEST_URL, proxy=real_proxy, timeout=5, allow_redirects=False) as response:
  File "/home/python/.virtualenvs/Env1/lib/python3.5/site-packages/aiohttp/client.py", line 690, in __aenter__
    self._resp = yield from self._coro
  File "/home/python/.virtualenvs/Env1/lib/python3.5/site-packages/aiohttp/client.py", line 341, in _request
    break
  File "/home/python/.virtualenvs/Env1/lib/python3.5/site-packages/aiohttp/helpers.py", line 732, in __exit__
    raise asyncio.TimeoutError from None
concurrent.futures._base.TimeoutError

During handling of the above exception, another exception occurred:

Traceback (most recent call last):
  File "/usr/lib/python3.5/asyncio/tasks.py", line 241, in _step
    result = coro.throw(exc)
  File "/home/python/Desktop/spider3/ProxyPool/proxypool/tester.py", line 44, in test_single_proxy
    self.redis.decrease(proxy)
  File "/home/python/Desktop/spider3/ProxyPool/proxypool/db.py", line 77, in decrease
    logger.info('代理%s, 当前分数%d移除' % (proxy, score))
TypeError: %d format: a number is required, not NoneType
2018-09-21 21:57:49,725 - asyncio - ERROR - Task exception was never retrieved
future: <Task finished coro=<Tester.test_single_proxy() done, defined at /home/python/Desktop/spider3/ProxyPool/proxypool/tester.py:20> exception=TypeError('%d format: a number is required, not NoneType',)>
Traceback (most recent call last):
  File "/home/python/Desktop/spider3/ProxyPool/proxypool/tester.py", line 35, in test_single_proxy
    async with session.get(TEST_URL, proxy=real_proxy, timeout=5, allow_redirects=False) as response:
  File "/home/python/.virtualenvs/Env1/lib/python3.5/site-packages/aiohttp/client.py", line 690, in __aenter__
    self._resp = yield from self._coro
  File "/home/python/.virtualenvs/Env1/lib/python3.5/site-packages/aiohttp/client.py", line 341, in _request
    break
  File "/home/python/.virtualenvs/Env1/lib/python3.5/site-packages/aiohttp/helpers.py", line 732, in __exit__
    raise asyncio.TimeoutError from None
concurrent.futures._base.TimeoutError

During handling of the above exception, another exception occurred:

Traceback (most recent call last):
  File "/usr/lib/python3.5/asyncio/tasks.py", line 241, in _step
    result = coro.throw(exc)
  File "/home/python/Desktop/spider3/ProxyPool/proxypool/tester.py", line 44, in test_single_proxy
    self.redis.decrease(proxy)
  File "/home/python/Desktop/spider3/ProxyPool/proxypool/db.py", line 77, in decrease
    logger.info('代理%s, 当前分数%d移除' % (proxy, score))
TypeError: %d format: a number is required, not NoneType
2018-09-21 21:59:17,703 - tester - ERROR - 测试器发生错误Set of coroutines/Futures is empty.
Traceback (most recent call last):
  File "/home/python/Desktop/spider3/ProxyPool/proxypool/tester.py", line 66, in run
    loop.run_until_complete(asyncio.wait(tasks))
  File "/usr/lib/python3.5/asyncio/base_events.py", line 387, in run_until_complete
    return future.result()
  File "/usr/lib/python3.5/asyncio/futures.py", line 274, in result
    raise self._exception
  File "/usr/lib/python3.5/asyncio/tasks.py", line 239, in _step
    result = coro.send(None)
  File "/usr/lib/python3.5/asyncio/tasks.py", line 338, in wait
    raise ValueError('Set of coroutines/Futures is empty.')
ValueError: Set of coroutines/Futures is empty.
2018-09-21 21:59:24,707 - tester - ERROR - 测试器发生错误Set of coroutines/Futures is empty.
Traceback (most recent call last):
  File "/home/python/Desktop/spider3/ProxyPool/proxypool/tester.py", line 66, in run
    loop.run_until_complete(asyncio.wait(tasks))
  File "/usr/lib/python3.5/asyncio/base_events.py", line 387, in run_until_complete
    return future.result()
  File "/usr/lib/python3.5/asyncio/futures.py", line 274, in result
    raise self._exception
  File "/usr/lib/python3.5/asyncio/tasks.py", line 239, in _step
    result = coro.send(None)
  File "/usr/lib/python3.5/asyncio/tasks.py", line 338, in wait
    raise ValueError('Set of coroutines/Futures is empty.')
ValueError: Set of coroutines/Futures is empty.
